2020-11-10 06:45:50 WARNING (MainThread) [homeassistant.loader] You are using a custom integration for shelly which has not been tested by Home Assistant. This component might cause stability problems, be sure to disable it if you experience issues with Home Assistant.
2020-11-10 06:45:50 WARNING (MainThread) [homeassistant.loader] You are using a custom integration for breaking_changes which has not been tested by Home Assistant. This component might cause stability problems, be sure to disable it if you experience issues with Home Assistant.
2020-11-10 06:45:50 WARNING (MainThread) [homeassistant.loader] You are using a custom integration for hacs which has not been tested by Home Assistant. This component might cause stability problems, be sure to disable it if you experience issues with Home Assistant.
2020-11-10 06:46:02 WARNING (MainThread) [homeassistant.setup] Setup of recorder is taking over 10 seconds.
2020-11-10 06:46:51 WARNING (MainThread) [homeassistant.bootstrap] Waiting on integrations to complete setup: recorder
2020-11-10 06:47:51 WARNING (MainThread) [homeassistant.bootstrap] Waiting on integrations to complete setup: recorder
2020-11-10 06:48:51 WARNING (MainThread) [homeassistant.bootstrap] Waiting on integrations to complete setup: recorder
2020-11-10 06:49:51 WARNING (MainThread) [homeassistant.bootstrap] Waiting on integrations to complete setup: recorder
2020-11-10 06:50:51 WARNING (MainThread) [homeassistant.bootstrap] Waiting on integrations to complete setup: recorder
2020-11-10 06:51:51 WARNING (MainThread) [homeassistant.bootstrap] Waiting on integrations to complete setup: recorder
2020-11-10 06:52:51 WARNING (MainThread) [homeassistant.bootstrap] Waiting on integrations to complete setup: recorder
2020-11-10 06:53:51 WARNING (MainThread) [homeassistant.bootstrap] Waiting on integrations to complete setup: recorder
2020-11-10 06:54:51 WARNING (MainThread) [homeassistant.bootstrap] Waiting on integrations to complete setup: recorder
2020-11-10 06:55:51 WARNING (MainThread) [homeassistant.bootstrap] Waiting on integrations to complete setup: recorder
2020-11-10 06:56:52 WARNING (MainThread) [homeassistant.bootstrap] Waiting on integrations to complete setup: recorder
2020-11-10 06:56:55 WARNING (Recorder) [homeassistant.components.recorder] Ended unfinished session (id=214 from 2020-11-10 05:09:21.923775)
2020-11-10 06:57:04 ERROR (MainThread) [homeassistant.config] Invalid config for [automation]: must contain at least one of service, service_template. @ data['action'][0]. Got None. (See /config/configuration.yaml, line 48). 
2020-11-10 06:57:09 ERROR (MainThread) [homeassistant.components.climate] The zwave platform for the climate integration does not support platform setup. Please remove it from your config.
2020-11-10 06:57:13 ERROR (MainThread) [snitun.client.client_peer] Challenge/Response error with SniTun server
2020-11-10 06:57:13 ERROR (MainThread) [hass_nabucasa.remote] Connection problem to snitun server
2020-11-10 06:57:14 WARNING (MainThread) [homeassistant.setup] Setup of input_boolean is taking over 10 seconds.
2020-11-10 06:57:14 WARNING (MainThread) [homeassistant.components.mobile_app.notify] Found duplicate device name iPhone
2020-11-10 06:57:14 WARNING (MainThread) [homeassistant.components.mobile_app.notify] Found duplicate device name iPhone
2020-11-10 06:57:14 ERROR (MainThread) [homeassistant.components.weather] Platform met does not generate unique IDs. ID home already exists - ignoring weather.home
2020-11-10 07:02:18 WARNING (MainThread) [homeassistant.components.zwave] Z-Wave not ready after 300 seconds, continuing anyway
2020-11-10 07:14:17 WARNING (MainThread) [homeassistant.components.mobile_app.notify] Found duplicate device name iPhone
2020-11-10 07:14:17 WARNING (MainThread) [homeassistant.components.mobile_app.notify] Found duplicate device name iPhone
2020-11-10 07:31:11 WARNING (MainThread) [homeassistant.components.light.reproduce_state] The use of other attributes than device state attributes is deprecated and will be removed in a future release. Invalid attributes are ['brightness_pct', 'transition']. Read the logs for further details: https://www.home-assistant.io/integrations/scene/
2020-11-10 07:31:11 WARNING (MainThread) [homeassistant.components.light.reproduce_state] The use of other attributes than device state attributes is deprecated and will be removed in a future release. Invalid attributes are ['brightness_pct']. Read the logs for further details: https://www.home-assistant.io/integrations/scene/
2020-11-10 07:31:11 WARNING (MainThread) [homeassistant.components.light.reproduce_state] The use of other attributes than device state attributes is deprecated and will be removed in a future release. Invalid attributes are ['brightness_pct']. Read the logs for further details: https://www.home-assistant.io/integrations/scene/
2020-11-10 07:31:11 WARNING (MainThread) [homeassistant.components.light.reproduce_state] The use of other attributes than device state attributes is deprecated and will be removed in a future release. Invalid attributes are ['brightness_pct']. Read the logs for further details: https://www.home-assistant.io/integrations/scene/
2020-11-10 07:31:11 WARNING (MainThread) [homeassistant.components.light.reproduce_state] The use of other attributes than device state attributes is deprecated and will be removed in a future release. Invalid attributes are ['brightness_pct']. Read the logs for further details: https://www.home-assistant.io/integrations/scene/
2020-11-10 07:31:11 WARNING (MainThread) [homeassistant.components.light.reproduce_state] The use of other attributes than device state attributes is deprecated and will be removed in a future release. Invalid attributes are ['brightness_pct']. Read the logs for further details: https://www.home-assistant.io/integrations/scene/
2020-11-10 08:02:42 WARNING (MainThread) [homeassistant.components.media_player] Updating braviatv media_player took longer than the scheduled update interval 0:00:10
2020-11-10 08:02:42 WARNING (MainThread) [homeassistant.helpers.entity] Update of media_player.sony_bravia_tv is taking over 10 seconds
2020-11-10 11:58:51 ERROR (MainThread) [homeassistant.components.ipp] Error requesting ipp data: Response payload is not completed
2020-11-10 12:24:26 ERROR (MainThread) [homeassistant.components.ipp] Timeout fetching ipp data
2020-11-10 12:44:39 ERROR (MainThread) [homeassistant.components.ipp] Error requesting ipp data: Response payload is not completed
2020-11-10 12:48:39 ERROR (MainThread) [homeassistant.components.ipp] Error requesting ipp data: Response payload is not completed
2020-11-10 12:54:44 ERROR (MainThread) [homeassistant.components.ipp] Error requesting ipp data: Response payload is not completed
2020-11-10 12:57:47 ERROR (MainThread) [homeassistant.components.ipp] Error requesting ipp data: Response payload is not completed
2020-11-10 13:02:52 ERROR (MainThread) [homeassistant.components.ipp] Error requesting ipp data: Response payload is not completed
2020-11-10 13:07:54 ERROR (MainThread) [homeassistant.components.ipp] Error requesting ipp data: Response payload is not completed
2020-11-10 13:17:15 ERROR (MainThread) [homeassistant.components.ipp] Error fetching ipp data: Invalid response from API: Timeout occurred while connecting to IPP server.
2020-11-10 13:42:39 ERROR (MainThread) [homeassistant.components.ipp] Timeout fetching ipp data
2020-11-10 13:44:58 ERROR (MainThread) [homeassistant.components.ipp] Error fetching ipp data: Invalid response from API: Timeout occurred while connecting to IPP server.
2020-11-10 13:53:01 ERROR (MainThread) [homeassistant.components.ipp] Error requesting ipp data: Response payload is not completed
2020-11-10 14:01:35 ERROR (MainThread) [homeassistant.components.ipp] Error requesting ipp data: Response payload is not completed
2020-11-10 16:41:19 ERROR (MainThread) [homeassistant.components.automation.turn_outdoor_lights_on] turn outdoor lights on: Error executing script. Invalid data for call_service at pos 3: must contain at least one of entity_id, area_id.
2020-11-10 16:41:19 ERROR (MainThread) [homeassistant.components.automation.turn_outdoor_lights_on] While executing automation automation.turn_outdoor_lights_on
Traceback (most recent call last):
  File "/usr/local/lib/python3.8/site-packages/voluptuous/schema_builder.py", line 272, in __call__
    return self._compiled([], data)
  File "/usr/local/lib/python3.8/site-packages/voluptuous/schema_builder.py", line 817, in validate_callable
    return schema(data)
  File "/usr/src/homeassistant/homeassistant/helpers/config_validation.py", line 129, in validate
    raise vol.Invalid("must contain at least one of {}.".format(", ".join(keys)))
voluptuous.error.Invalid: must contain at least one of entity_id, area_id.

During handling of the above exception, another exception occurred:

Traceback (most recent call last):
  File "/usr/src/homeassistant/homeassistant/components/automation/__init__.py", line 426, in async_trigger
    await self.action_script.async_run(
  File "/usr/src/homeassistant/homeassistant/helpers/script.py", line 1010, in async_run
    await asyncio.shield(run.async_run())
  File "/usr/src/homeassistant/homeassistant/helpers/script.py", line 245, in async_run
    await self._async_step(log_exceptions=False)
  File "/usr/src/homeassistant/homeassistant/helpers/script.py", line 253, in _async_step
    await getattr(
  File "/usr/src/homeassistant/homeassistant/helpers/script.py", line 460, in _async_call_service_step
    await service_task
  File "/usr/src/homeassistant/homeassistant/core.py", line 1402, in async_call
    processed_data = handler.schema(service_data)
  File "/usr/local/lib/python3.8/site-packages/voluptuous/validators.py", line 218, in __call__
    return self._exec((Schema(val) for val in self.validators), v)
  File "/usr/local/lib/python3.8/site-packages/voluptuous/validators.py", line 340, in _exec
    raise e if self.msg is None else AllInvalid(self.msg, path=path)
  File "/usr/local/lib/python3.8/site-packages/voluptuous/validators.py", line 336, in _exec
    v = func(v)
  File "/usr/local/lib/python3.8/site-packages/voluptuous/schema_builder.py", line 276, in __call__
    raise er.MultipleInvalid([e])
voluptuous.error.MultipleInvalid: must contain at least one of entity_id, area_id.
2020-11-10 17:12:59 WARNING (MainThread) [homeassistant.components.mobile_app.notify] Found duplicate device name iPhone
2020-11-10 17:12:59 WARNING (MainThread) [homeassistant.components.mobile_app.notify] Found duplicate device name iPhone
2020-11-10 17:12:59 WARNING (MainThread) [homeassistant.components.mobile_app.notify] Found duplicate device name iPhone
2020-11-10 17:12:59 WARNING (MainThread) [homeassistant.components.mobile_app.notify] Found duplicate device name iPhone
2020-11-10 22:05:20 WARNING (MainThread) [homeassistant.components.esphome] Error getting initial data for 192.168.1.159: Timeout while waiting for API response!
2020-11-10 22:05:40 WARNING (MainThread) [homeassistant.components.esphome] Error getting initial data for 192.168.1.159: Timeout while waiting for API response!
2020-11-10 22:27:30 WARNING (MainThread) [homeassistant.components.esphome] Error getting initial data for 192.168.1.159: Timeout while waiting for API response!
2020-11-10 22:51:07 WARNING (MainThread) [homeassistant.components.light.reproduce_state] Unable to find entity light.living_room_chand
2020-11-10 22:51:07 WARNING (MainThread) [homeassistant.components.light.reproduce_state] The use of other attributes than device state attributes is deprecated and will be removed in a future release. Invalid attributes are ['transition']. Read the logs for further details: https://www.home-assistant.io/integrations/scene/
2020-11-10 22:51:07 WARNING (MainThread) [homeassistant.components.light.reproduce_state] The use of other attributes than device state attributes is deprecated and will be removed in a future release. Invalid attributes are ['transition', 'brightness_pct']. Read the logs for further details: https://www.home-assistant.io/integrations/scene/
2020-11-10 22:51:07 WARNING (MainThread) [homeassistant.components.light.reproduce_state] The use of other attributes than device state attributes is deprecated and will be removed in a future release. Invalid attributes are ['transition', 'brightness_pct']. Read the logs for further details: https://www.home-assistant.io/integrations/scene/
2020-11-10 22:51:07 WARNING (MainThread) [homeassistant.components.light.reproduce_state] The use of other attributes than device state attributes is deprecated and will be removed in a future release. Invalid attributes are ['transition', 'brightness_pct']. Read the logs for further details: https://www.home-assistant.io/integrations/scene/
2020-11-10 22:51:18 WARNING (MainThread) [homeassistant.components.light.reproduce_state] Unable to find entity light.living_room_chand
2020-11-10 22:51:18 WARNING (MainThread) [homeassistant.components.light.reproduce_state] The use of other attributes than device state attributes is deprecated and will be removed in a future release. Invalid attributes are ['transition']. Read the logs for further details: https://www.home-assistant.io/integrations/scene/
2020-11-10 22:51:18 WARNING (MainThread) [homeassistant.components.light.reproduce_state] The use of other attributes than device state attributes is deprecated and will be removed in a future release. Invalid attributes are ['transition', 'brightness_pct']. Read the logs for further details: https://www.home-assistant.io/integrations/scene/
2020-11-10 22:51:18 WARNING (MainThread) [homeassistant.components.light.reproduce_state] The use of other attributes than device state attributes is deprecated and will be removed in a future release. Invalid attributes are ['transition', 'brightness_pct']. Read the logs for further details: https://www.home-assistant.io/integrations/scene/
2020-11-10 22:51:18 WARNING (MainThread) [homeassistant.components.light.reproduce_state] The use of other attributes than device state attributes is deprecated and will be removed in a future release. Invalid attributes are ['transition', 'brightness_pct']. Read the logs for further details: https://www.home-assistant.io/integrations/scene/
2020-11-10 22:51:30 WARNING (MainThread) [homeassistant.components.light.reproduce_state] Unable to find entity light.living_room_chand
2020-11-10 22:51:30 WARNING (MainThread) [homeassistant.components.light.reproduce_state] The use of other attributes than device state attributes is deprecated and will be removed in a future release. Invalid attributes are ['transition']. Read the logs for further details: https://www.home-assistant.io/integrations/scene/
2020-11-10 22:51:30 WARNING (MainThread) [homeassistant.components.light.reproduce_state] The use of other attributes than device state attributes is deprecated and will be removed in a future release. Invalid attributes are ['transition', 'brightness_pct']. Read the logs for further details: https://www.home-assistant.io/integrations/scene/
2020-11-10 22:51:30 WARNING (MainThread) [homeassistant.components.light.reproduce_state] The use of other attributes than device state attributes is deprecated and will be removed in a future release. Invalid attributes are ['transition', 'brightness_pct']. Read the logs for further details: https://www.home-assistant.io/integrations/scene/
2020-11-10 22:51:30 WARNING (MainThread) [homeassistant.components.light.reproduce_state] The use of other attributes than device state attributes is deprecated and will be removed in a future release. Invalid attributes are ['transition', 'brightness_pct']. Read the logs for further details: https://www.home-assistant.io/integrations/scene/
2020-11-10 23:58:04 WARNING (MainThread) [homeassistant.components.esphome] Error getting initial data for 192.168.1.159: Timeout while waiting for API response!
2020-11-11 00:00:21 WARNING (MainThread) [homeassistant.components.esphome] Error getting initial data for 192.168.1.159: Timeout while waiting for API response!
2020-11-11 00:11:53 WARNING (MainThread) [homeassistant.components.esphome] Error getting initial data for 192.168.1.252: Timeout while waiting for API response!
2020-11-11 00:22:45 WARNING (MainThread) [homeassistant.components.esphome] Error getting initial data for 192.168.1.252: Timeout while waiting for API response!
2020-11-11 00:22:59 WARNING (MainThread) [homeassistant.components.esphome] Error getting initial data for 192.168.1.252: Timeout while waiting for API response!
2020-11-11 00:25:12 WARNING (MainThread) [homeassistant.components.esphome] Error getting initial data for 192.168.1.252: Timeout while waiting for API response!
2020-11-11 00:31:16 WARNING (MainThread) [homeassistant.components.esphome] Error getting initial data for 192.168.1.252: Timeout while waiting for API response!
2020-11-11 00:33:50 WARNING (MainThread) [homeassistant.components.esphome] Error getting initial data for 192.168.1.252: Timeout while waiting for API response!
2020-11-11 03:21:14 ERROR (Thread-19) [pysonos.events] Exception received in Subscription.renew for Subscription to:
http://192.168.1.213:1400/MediaRenderer/AVTransport/Event, sid: uuid:RINCON_5CAAFDE0121A01400_sub0000000011
Traceback (most recent call last):
  File "/usr/local/lib/python3.8/site-packages/urllib3/connection.py", line 159, in _new_conn
    conn = connection.create_connection(
  File "/usr/local/lib/python3.8/site-packages/urllib3/util/connection.py", line 84, in create_connection
    raise err
  File "/usr/local/lib/python3.8/site-packages/urllib3/util/connection.py", line 74, in create_connection
    sock.connect(sa)
ConnectionRefusedError: [Errno 111] Connection refused

During handling of the above exception, another exception occurred:

Traceback (most recent call last):
  File "/usr/local/lib/python3.8/site-packages/urllib3/connectionpool.py", line 670, in urlopen
    httplib_response = self._make_request(
  File "/usr/local/lib/python3.8/site-packages/urllib3/connectionpool.py", line 392, in _make_request
    conn.request(method, url, **httplib_request_kw)
  File "/usr/local/lib/python3.8/http/client.py", line 1255, in request
    self._send_request(method, url, body, headers, encode_chunked)
  File "/usr/local/lib/python3.8/http/client.py", line 1301, in _send_request
    self.endheaders(body, encode_chunked=encode_chunked)
  File "/usr/local/lib/python3.8/http/client.py", line 1250, in endheaders
    self._send_output(message_body, encode_chunked=encode_chunked)
  File "/usr/local/lib/python3.8/http/client.py", line 1010, in _send_output
    self.send(msg)
  File "/usr/local/lib/python3.8/http/client.py", line 950, in send
    self.connect()
  File "/usr/local/lib/python3.8/site-packages/urllib3/connection.py", line 187, in connect
    conn = self._new_conn()
  File "/usr/local/lib/python3.8/site-packages/urllib3/connection.py", line 171, in _new_conn
    raise NewConnectionError(
urllib3.exceptions.NewConnectionError: <urllib3.connection.HTTPConnection object at 0x7f8d068ee4c0>: Failed to establish a new connection: [Errno 111] Connection refused

During handling of the above exception, another exception occurred:

Traceback (most recent call last):
  File "/usr/local/lib/python3.8/site-packages/requests/adapters.py", line 439, in send
    resp = conn.urlopen(
  File "/usr/local/lib/python3.8/site-packages/urllib3/connectionpool.py", line 726, in urlopen
    retries = retries.increment(
  File "/usr/local/lib/python3.8/site-packages/urllib3/util/retry.py", line 446, in increment
    raise MaxRetryError(_pool, url, error or ResponseError(cause))
urllib3.exceptions.MaxRetryError: HTTPConnectionPool(host='192.168.1.213', port=1400): Max retries exceeded with url: /MediaRenderer/AVTransport/Event (Caused by NewConnectionError('<urllib3.connection.HTTPConnection object at 0x7f8d068ee4c0>: Failed to establish a new connection: [Errno 111] Connection refused'))

During handling of the above exception, another exception occurred:

Traceback (most recent call last):
  File "/usr/local/lib/python3.8/site-packages/pysonos/events.py", line 433, in _wrap
    method(*args, **kwargs)
  File "/usr/local/lib/python3.8/site-packages/pysonos/events_base.py", line 542, in renew
    return self._request(
  File "/usr/local/lib/python3.8/site-packages/pysonos/events.py", line 389, in _request
    response = requests.request(
  File "/usr/local/lib/python3.8/site-packages/requests/api.py", line 61, in request
    return session.request(method=method, url=url, **kwargs)
  File "/usr/local/lib/python3.8/site-packages/requests/sessions.py", line 530, in request
    resp = self.send(prep, **send_kwargs)
  File "/usr/local/lib/python3.8/site-packages/requests/sessions.py", line 643, in send
    r = adapter.send(request, **kwargs)
  File "/usr/local/lib/python3.8/site-packages/requests/adapters.py", line 516, in send
    raise ConnectionError(e, request=request)
requests.exceptions.ConnectionError: HTTPConnectionPool(host='192.168.1.213', port=1400): Max retries exceeded with url: /MediaRenderer/AVTransport/Event (Caused by NewConnectionError('<urllib3.connection.HTTPConnection object at 0x7f8d068ee4c0>: Failed to establish a new connection: [Errno 111] Connection refused'))
2020-11-11 03:21:14 ERROR (Thread-20) [pysonos.events] Exception received in Subscription.renew for Subscription to:
http://192.168.1.213:1400/MediaRenderer/RenderingControl/Event, sid: uuid:RINCON_5CAAFDE0121A01400_sub0000000012
Traceback (most recent call last):
  File "/usr/local/lib/python3.8/site-packages/urllib3/connection.py", line 159, in _new_conn
    conn = connection.create_connection(
  File "/usr/local/lib/python3.8/site-packages/urllib3/util/connection.py", line 84, in create_connection
    raise err
  File "/usr/local/lib/python3.8/site-packages/urllib3/util/connection.py", line 74, in create_connection
    sock.connect(sa)
ConnectionRefusedError: [Errno 111] Connection refused

During handling of the above exception, another exception occurred:

Traceback (most recent call last):
  File "/usr/local/lib/python3.8/site-packages/urllib3/connectionpool.py", line 670, in urlopen
    httplib_response = self._make_request(
  File "/usr/local/lib/python3.8/site-packages/urllib3/connectionpool.py", line 392, in _make_request
    conn.request(method, url, **httplib_request_kw)
  File "/usr/local/lib/python3.8/http/client.py", line 1255, in request
    self._send_request(method, url, body, headers, encode_chunked)
  File "/usr/local/lib/python3.8/http/client.py", line 1301, in _send_request
    self.endheaders(body, encode_chunked=encode_chunked)
  File "/usr/local/lib/python3.8/http/client.py", line 1250, in endheaders
    self._send_output(message_body, encode_chunked=encode_chunked)
  File "/usr/local/lib/python3.8/http/client.py", line 1010, in _send_output
    self.send(msg)
  File "/usr/local/lib/python3.8/http/client.py", line 950, in send
    self.connect()
  File "/usr/local/lib/python3.8/site-packages/urllib3/connection.py", line 187, in connect
    conn = self._new_conn()
  File "/usr/local/lib/python3.8/site-packages/urllib3/connection.py", line 171, in _new_conn
    raise NewConnectionError(
urllib3.exceptions.NewConnectionError: <urllib3.connection.HTTPConnection object at 0x7f8d86755730>: Failed to establish a new connection: [Errno 111] Connection refused

During handling of the above exception, another exception occurred:

Traceback (most recent call last):
  File "/usr/local/lib/python3.8/site-packages/requests/adapters.py", line 439, in send
    resp = conn.urlopen(
  File "/usr/local/lib/python3.8/site-packages/urllib3/connectionpool.py", line 726, in urlopen
    retries = retries.increment(
  File "/usr/local/lib/python3.8/site-packages/urllib3/util/retry.py", line 446, in increment
    raise MaxRetryError(_pool, url, error or ResponseError(cause))
urllib3.exceptions.MaxRetryError: HTTPConnectionPool(host='192.168.1.213', port=1400): Max retries exceeded with url: /MediaRenderer/RenderingControl/Event (Caused by NewConnectionError('<urllib3.connection.HTTPConnection object at 0x7f8d86755730>: Failed to establish a new connection: [Errno 111] Connection refused'))

During handling of the above exception, another exception occurred:

Traceback (most recent call last):
  File "/usr/local/lib/python3.8/site-packages/pysonos/events.py", line 433, in _wrap
    method(*args, **kwargs)
  File "/usr/local/lib/python3.8/site-packages/pysonos/events_base.py", line 542, in renew
    return self._request(
  File "/usr/local/lib/python3.8/site-packages/pysonos/events.py", line 389, in _request
    response = requests.request(
  File "/usr/local/lib/python3.8/site-packages/requests/api.py", line 61, in request
    return session.request(method=method, url=url, **kwargs)
  File "/usr/local/lib/python3.8/site-packages/requests/sessions.py", line 530, in request
    resp = self.send(prep, **send_kwargs)
  File "/usr/local/lib/python3.8/site-packages/requests/sessions.py", line 643, in send
    r = adapter.send(request, **kwargs)
  File "/usr/local/lib/python3.8/site-packages/requests/adapters.py", line 516, in send
    raise ConnectionError(e, request=request)
requests.exceptions.ConnectionError: HTTPConnectionPool(host='192.168.1.213', port=1400): Max retries exceeded with url: /MediaRenderer/RenderingControl/Event (Caused by NewConnectionError('<urllib3.connection.HTTPConnection object at 0x7f8d86755730>: Failed to establish a new connection: [Errno 111] Connection refused'))
2020-11-11 03:21:14 ERROR (Thread-21) [pysonos.events] Exception received in Subscription.renew for Subscription to:
http://192.168.1.213:1400/ZoneGroupTopology/Event, sid: uuid:RINCON_5CAAFDE0121A01400_sub0000000013
Traceback (most recent call last):
  File "/usr/local/lib/python3.8/site-packages/urllib3/connection.py", line 159, in _new_conn
    conn = connection.create_connection(
  File "/usr/local/lib/python3.8/site-packages/urllib3/util/connection.py", line 84, in create_connection
    raise err
  File "/usr/local/lib/python3.8/site-packages/urllib3/util/connection.py", line 74, in create_connection
    sock.connect(sa)
ConnectionRefusedError: [Errno 111] Connection refused

During handling of the above exception, another exception occurred:

Traceback (most recent call last):
  File "/usr/local/lib/python3.8/site-packages/urllib3/connectionpool.py", line 670, in urlopen
    httplib_response = self._make_request(
  File "/usr/local/lib/python3.8/site-packages/urllib3/connectionpool.py", line 392, in _make_request
    conn.request(method, url, **httplib_request_kw)
  File "/usr/local/lib/python3.8/http/client.py", line 1255, in request
    self._send_request(method, url, body, headers, encode_chunked)
  File "/usr/local/lib/python3.8/http/client.py", line 1301, in _send_request
    self.endheaders(body, encode_chunked=encode_chunked)
  File "/usr/local/lib/python3.8/http/client.py", line 1250, in endheaders
    self._send_output(message_body, encode_chunked=encode_chunked)
  File "/usr/local/lib/python3.8/http/client.py", line 1010, in _send_output
    self.send(msg)
  File "/usr/local/lib/python3.8/http/client.py", line 950, in send
    self.connect()
  File "/usr/local/lib/python3.8/site-packages/urllib3/connection.py", line 187, in connect
    conn = self._new_conn()
  File "/usr/local/lib/python3.8/site-packages/urllib3/connection.py", line 171, in _new_conn
    raise NewConnectionError(
urllib3.exceptions.NewConnectionError: <urllib3.connection.HTTPConnection object at 0x7f8d7ed7e1f0>: Failed to establish a new connection: [Errno 111] Connection refused

During handling of the above exception, another exception occurred:

Traceback (most recent call last):
  File "/usr/local/lib/python3.8/site-packages/requests/adapters.py", line 439, in send
    resp = conn.urlopen(
  File "/usr/local/lib/python3.8/site-packages/urllib3/connectionpool.py", line 726, in urlopen
    retries = retries.increment(
  File "/usr/local/lib/python3.8/site-packages/urllib3/util/retry.py", line 446, in increment
    raise MaxRetryError(_pool, url, error or ResponseError(cause))
urllib3.exceptions.MaxRetryError: HTTPConnectionPool(host='192.168.1.213', port=1400): Max retries exceeded with url: /ZoneGroupTopology/Event (Caused by NewConnectionError('<urllib3.connection.HTTPConnection object at 0x7f8d7ed7e1f0>: Failed to establish a new connection: [Errno 111] Connection refused'))

During handling of the above exception, another exception occurred:

Traceback (most recent call last):
  File "/usr/local/lib/python3.8/site-packages/pysonos/events.py", line 433, in _wrap
    method(*args, **kwargs)
  File "/usr/local/lib/python3.8/site-packages/pysonos/events_base.py", line 542, in renew
    return self._request(
  File "/usr/local/lib/python3.8/site-packages/pysonos/events.py", line 389, in _request
    response = requests.request(
  File "/usr/local/lib/python3.8/site-packages/requests/api.py", line 61, in request
    return session.request(method=method, url=url, **kwargs)
  File "/usr/local/lib/python3.8/site-packages/requests/sessions.py", line 530, in request
    resp = self.send(prep, **send_kwargs)
  File "/usr/local/lib/python3.8/site-packages/requests/sessions.py", line 643, in send
    r = adapter.send(request, **kwargs)
  File "/usr/local/lib/python3.8/site-packages/requests/adapters.py", line 516, in send
    raise ConnectionError(e, request=request)
requests.exceptions.ConnectionError: HTTPConnectionPool(host='192.168.1.213', port=1400): Max retries exceeded with url: /ZoneGroupTopology/Event (Caused by NewConnectionError('<urllib3.connection.HTTPConnection object at 0x7f8d7ed7e1f0>: Failed to establish a new connection: [Errno 111] Connection refused'))
2020-11-11 03:21:15 ERROR (Thread-23) [pysonos.events] Exception received in Subscription.renew for Subscription to:
http://192.168.1.251:1400/MediaRenderer/AVTransport/Event, sid: uuid:RINCON_347E5C03124B01400_sub0000000026
Traceback (most recent call last):
  File "/usr/local/lib/python3.8/site-packages/urllib3/connection.py", line 159, in _new_conn
    conn = connection.create_connection(
  File "/usr/local/lib/python3.8/site-packages/urllib3/util/connection.py", line 84, in create_connection
    raise err
  File "/usr/local/lib/python3.8/site-packages/urllib3/util/connection.py", line 74, in create_connection
    sock.connect(sa)
ConnectionRefusedError: [Errno 111] Connection refused

During handling of the above exception, another exception occurred:

Traceback (most recent call last):
  File "/usr/local/lib/python3.8/site-packages/urllib3/connectionpool.py", line 670, in urlopen
    httplib_response = self._make_request(
  File "/usr/local/lib/python3.8/site-packages/urllib3/connectionpool.py", line 392, in _make_request
    conn.request(method, url, **httplib_request_kw)
  File "/usr/local/lib/python3.8/http/client.py", line 1255, in request
    self._send_request(method, url, body, headers, encode_chunked)
  File "/usr/local/lib/python3.8/http/client.py", line 1301, in _send_request
    self.endheaders(body, encode_chunked=encode_chunked)
  File "/usr/local/lib/python3.8/http/client.py", line 1250, in endheaders
    self._send_output(message_body, encode_chunked=encode_chunked)
  File "/usr/local/lib/python3.8/http/client.py", line 1010, in _send_output
    self.send(msg)
  File "/usr/local/lib/python3.8/http/client.py", line 950, in send
    self.connect()
  File "/usr/local/lib/python3.8/site-packages/urllib3/connection.py", line 187, in connect
    conn = self._new_conn()
  File "/usr/local/lib/python3.8/site-packages/urllib3/connection.py", line 171, in _new_conn
    raise NewConnectionError(
urllib3.exceptions.NewConnectionError: <urllib3.connection.HTTPConnection object at 0x7f8d066cc850>: Failed to establish a new connection: [Errno 111] Connection refused

During handling of the above exception, another exception occurred:

Traceback (most recent call last):
  File "/usr/local/lib/python3.8/site-packages/requests/adapters.py", line 439, in send
    resp = conn.urlopen(
  File "/usr/local/lib/python3.8/site-packages/urllib3/connectionpool.py", line 726, in urlopen
    retries = retries.increment(
  File "/usr/local/lib/python3.8/site-packages/urllib3/util/retry.py", line 446, in increment
    raise MaxRetryError(_pool, url, error or ResponseError(cause))
urllib3.exceptions.MaxRetryError: HTTPConnectionPool(host='192.168.1.251', port=1400): Max retries exceeded with url: /MediaRenderer/AVTransport/Event (Caused by NewConnectionError('<urllib3.connection.HTTPConnection object at 0x7f8d066cc850>: Failed to establish a new connection: [Errno 111] Connection refused'))

During handling of the above exception, another exception occurred:

Traceback (most recent call last):
  File "/usr/local/lib/python3.8/site-packages/pysonos/events.py", line 433, in _wrap
    method(*args, **kwargs)
  File "/usr/local/lib/python3.8/site-packages/pysonos/events_base.py", line 542, in renew
    return self._request(
  File "/usr/local/lib/python3.8/site-packages/pysonos/events.py", line 389, in _request
    response = requests.request(
  File "/usr/local/lib/python3.8/site-packages/requests/api.py", line 61, in request
    return session.request(method=method, url=url, **kwargs)
  File "/usr/local/lib/python3.8/site-packages/requests/sessions.py", line 530, in request
    resp = self.send(prep, **send_kwargs)
  File "/usr/local/lib/python3.8/site-packages/requests/sessions.py", line 643, in send
    r = adapter.send(request, **kwargs)
  File "/usr/local/lib/python3.8/site-packages/requests/adapters.py", line 516, in send
    raise ConnectionError(e, request=request)
requests.exceptions.ConnectionError: HTTPConnectionPool(host='192.168.1.251', port=1400): Max retries exceeded with url: /MediaRenderer/AVTransport/Event (Caused by NewConnectionError('<urllib3.connection.HTTPConnection object at 0x7f8d066cc850>: Failed to establish a new connection: [Errno 111] Connection refused'))
2020-11-11 03:21:15 ERROR (Thread-22) [pysonos.events] Exception received in Subscription.renew for Subscription to:
http://192.168.1.213:1400/MediaServer/ContentDirectory/Event, sid: uuid:RINCON_5CAAFDE0121A01400_sub0000000014
Traceback (most recent call last):
  File "/usr/local/lib/python3.8/site-packages/urllib3/connection.py", line 159, in _new_conn
    conn = connection.create_connection(
  File "/usr/local/lib/python3.8/site-packages/urllib3/util/connection.py", line 84, in create_connection
    raise err
  File "/usr/local/lib/python3.8/site-packages/urllib3/util/connection.py", line 74, in create_connection
    sock.connect(sa)
ConnectionRefusedError: [Errno 111] Connection refused

During handling of the above exception, another exception occurred:

Traceback (most recent call last):
  File "/usr/local/lib/python3.8/site-packages/urllib3/connectionpool.py", line 670, in urlopen
    httplib_response = self._make_request(
  File "/usr/local/lib/python3.8/site-packages/urllib3/connectionpool.py", line 392, in _make_request
    conn.request(method, url, **httplib_request_kw)
  File "/usr/local/lib/python3.8/http/client.py", line 1255, in request
    self._send_request(method, url, body, headers, encode_chunked)
  File "/usr/local/lib/python3.8/http/client.py", line 1301, in _send_request
    self.endheaders(body, encode_chunked=encode_chunked)
  File "/usr/local/lib/python3.8/http/client.py", line 1250, in endheaders
    self._send_output(message_body, encode_chunked=encode_chunked)
  File "/usr/local/lib/python3.8/http/client.py", line 1010, in _send_output
    self.send(msg)
  File "/usr/local/lib/python3.8/http/client.py", line 950, in send
    self.connect()
  File "/usr/local/lib/python3.8/site-packages/urllib3/connection.py", line 187, in connect
    conn = self._new_conn()
  File "/usr/local/lib/python3.8/site-packages/urllib3/connection.py", line 171, in _new_conn
    raise NewConnectionError(
urllib3.exceptions.NewConnectionError: <urllib3.connection.HTTPConnection object at 0x7f8d86755f40>: Failed to establish a new connection: [Errno 111] Connection refused

During handling of the above exception, another exception occurred:

Traceback (most recent call last):
  File "/usr/local/lib/python3.8/site-packages/requests/adapters.py", line 439, in send
    resp = conn.urlopen(
  File "/usr/local/lib/python3.8/site-packages/urllib3/connectionpool.py", line 726, in urlopen
    retries = retries.increment(
  File "/usr/local/lib/python3.8/site-packages/urllib3/util/retry.py", line 446, in increment
    raise MaxRetryError(_pool, url, error or ResponseError(cause))
urllib3.exceptions.MaxRetryError: HTTPConnectionPool(host='192.168.1.213', port=1400): Max retries exceeded with url: /MediaServer/ContentDirectory/Event (Caused by NewConnectionError('<urllib3.connection.HTTPConnection object at 0x7f8d86755f40>: Failed to establish a new connection: [Errno 111] Connection refused'))

During handling of the above exception, another exception occurred:

Traceback (most recent call last):
  File "/usr/local/lib/python3.8/site-packages/pysonos/events.py", line 433, in _wrap
    method(*args, **kwargs)
  File "/usr/local/lib/python3.8/site-packages/pysonos/events_base.py", line 542, in renew
    return self._request(
  File "/usr/local/lib/python3.8/site-packages/pysonos/events.py", line 389, in _request
    response = requests.request(
  File "/usr/local/lib/python3.8/site-packages/requests/api.py", line 61, in request
    return session.request(method=method, url=url, **kwargs)
  File "/usr/local/lib/python3.8/site-packages/requests/sessions.py", line 530, in request
    resp = self.send(prep, **send_kwargs)
  File "/usr/local/lib/python3.8/site-packages/requests/sessions.py", line 643, in send
    r = adapter.send(request, **kwargs)
  File "/usr/local/lib/python3.8/site-packages/requests/adapters.py", line 516, in send
    raise ConnectionError(e, request=request)
requests.exceptions.ConnectionError: HTTPConnectionPool(host='192.168.1.213', port=1400): Max retries exceeded with url: /MediaServer/ContentDirectory/Event (Caused by NewConnectionError('<urllib3.connection.HTTPConnection object at 0x7f8d86755f40>: Failed to establish a new connection: [Errno 111] Connection refused'))
2020-11-11 03:21:15 ERROR (Thread-25) [pysonos.events] Exception received in Subscription.renew for Subscription to:
http://192.168.1.251:1400/MediaRenderer/RenderingControl/Event, sid: uuid:RINCON_347E5C03124B01400_sub0000000027
Traceback (most recent call last):
  File "/usr/local/lib/python3.8/site-packages/urllib3/connection.py", line 159, in _new_conn
    conn = connection.create_connection(
  File "/usr/local/lib/python3.8/site-packages/urllib3/util/connection.py", line 84, in create_connection
    raise err
  File "/usr/local/lib/python3.8/site-packages/urllib3/util/connection.py", line 74, in create_connection
    sock.connect(sa)
ConnectionRefusedError: [Errno 111] Connection refused

During handling of the above exception, another exception occurred:

Traceback (most recent call last):
  File "/usr/local/lib/python3.8/site-packages/urllib3/connectionpool.py", line 670, in urlopen
    httplib_response = self._make_request(
  File "/usr/local/lib/python3.8/site-packages/urllib3/connectionpool.py", line 392, in _make_request
    conn.request(method, url, **httplib_request_kw)
  File "/usr/local/lib/python3.8/http/client.py", line 1255, in request
    self._send_request(method, url, body, headers, encode_chunked)
  File "/usr/local/lib/python3.8/http/client.py", line 1301, in _send_request
    self.endheaders(body, encode_chunked=encode_chunked)
  File "/usr/local/lib/python3.8/http/client.py", line 1250, in endheaders
    self._send_output(message_body, encode_chunked=encode_chunked)
  File "/usr/local/lib/python3.8/http/client.py", line 1010, in _send_output
    self.send(msg)
  File "/usr/local/lib/python3.8/http/client.py", line 950, in send
    self.connect()
  File "/usr/local/lib/python3.8/site-packages/urllib3/connection.py", line 187, in connect
    conn = self._new_conn()
  File "/usr/local/lib/python3.8/site-packages/urllib3/connection.py", line 171, in _new_conn
    raise NewConnectionError(
urllib3.exceptions.NewConnectionError: <urllib3.connection.HTTPConnection object at 0x7f8d7f61eaf0>: Failed to establish a new connection: [Errno 111] Connection refused

During handling of the above exception, another exception occurred:

Traceback (most recent call last):
  File "/usr/local/lib/python3.8/site-packages/requests/adapters.py", line 439, in send
    resp = conn.urlopen(
  File "/usr/local/lib/python3.8/site-packages/urllib3/connectionpool.py", line 726, in urlopen
    retries = retries.increment(
  File "/usr/local/lib/python3.8/site-packages/urllib3/util/retry.py", line 446, in increment
    raise MaxRetryError(_pool, url, error or ResponseError(cause))
urllib3.exceptions.MaxRetryError: HTTPConnectionPool(host='192.168.1.251', port=1400): Max retries exceeded with url: /MediaRenderer/RenderingControl/Event (Caused by NewConnectionError('<urllib3.connection.HTTPConnection object at 0x7f8d7f61eaf0>: Failed to establish a new connection: [Errno 111] Connection refused'))

During handling of the above exception, another exception occurred:

Traceback (most recent call last):
  File "/usr/local/lib/python3.8/site-packages/pysonos/events.py", line 433, in _wrap
    method(*args, **kwargs)
  File "/usr/local/lib/python3.8/site-packages/pysonos/events_base.py", line 542, in renew
    return self._request(
  File "/usr/local/lib/python3.8/site-packages/pysonos/events.py", line 389, in _request
    response = requests.request(
  File "/usr/local/lib/python3.8/site-packages/requests/api.py", line 61, in request
    return session.request(method=method, url=url, **kwargs)
  File "/usr/local/lib/python3.8/site-packages/requests/sessions.py", line 530, in request
    resp = self.send(prep, **send_kwargs)
  File "/usr/local/lib/python3.8/site-packages/requests/sessions.py", line 643, in send
    r = adapter.send(request, **kwargs)
  File "/usr/local/lib/python3.8/site-packages/requests/adapters.py", line 516, in send
    raise ConnectionError(e, request=request)
requests.exceptions.ConnectionError: HTTPConnectionPool(host='192.168.1.251', port=1400): Max retries exceeded with url: /MediaRenderer/RenderingControl/Event (Caused by NewConnectionError('<urllib3.connection.HTTPConnection object at 0x7f8d7f61eaf0>: Failed to establish a new connection: [Errno 111] Connection refused'))
2020-11-11 03:21:15 ERROR (Thread-26) [pysonos.events] Exception received in Subscription.renew for Subscription to:
http://192.168.1.251:1400/ZoneGroupTopology/Event, sid: uuid:RINCON_347E5C03124B01400_sub0000000028
Traceback (most recent call last):
  File "/usr/local/lib/python3.8/site-packages/urllib3/connection.py", line 159, in _new_conn
    conn = connection.create_connection(
  File "/usr/local/lib/python3.8/site-packages/urllib3/util/connection.py", line 84, in create_connection
    raise err
  File "/usr/local/lib/python3.8/site-packages/urllib3/util/connection.py", line 74, in create_connection
    sock.connect(sa)
ConnectionRefusedError: [Errno 111] Connection refused

During handling of the above exception, another exception occurred:

Traceback (most recent call last):
  File "/usr/local/lib/python3.8/site-packages/urllib3/connectionpool.py", line 670, in urlopen
    httplib_response = self._make_request(
  File "/usr/local/lib/python3.8/site-packages/urllib3/connectionpool.py", line 392, in _make_request
    conn.request(method, url, **httplib_request_kw)
  File "/usr/local/lib/python3.8/http/client.py", line 1255, in request
    self._send_request(method, url, body, headers, encode_chunked)
  File "/usr/local/lib/python3.8/http/client.py", line 1301, in _send_request
    self.endheaders(body, encode_chunked=encode_chunked)
  File "/usr/local/lib/python3.8/http/client.py", line 1250, in endheaders
    self._send_output(message_body, encode_chunked=encode_chunked)
  File "/usr/local/lib/python3.8/http/client.py", line 1010, in _send_output
    self.send(msg)
  File "/usr/local/lib/python3.8/http/client.py", line 950, in send
    self.connect()
  File "/usr/local/lib/python3.8/site-packages/urllib3/connection.py", line 187, in connect
    conn = self._new_conn()
  File "/usr/local/lib/python3.8/site-packages/urllib3/connection.py", line 171, in _new_conn
    raise NewConnectionError(
urllib3.exceptions.NewConnectionError: <urllib3.connection.HTTPConnection object at 0x7f8d7ed6afa0>: Failed to establish a new connection: [Errno 111] Connection refused

During handling of the above exception, another exception occurred:

Traceback (most recent call last):
  File "/usr/local/lib/python3.8/site-packages/requests/adapters.py", line 439, in send
    resp = conn.urlopen(
  File "/usr/local/lib/python3.8/site-packages/urllib3/connectionpool.py", line 726, in urlopen
    retries = retries.increment(
  File "/usr/local/lib/python3.8/site-packages/urllib3/util/retry.py", line 446, in increment
    raise MaxRetryError(_pool, url, error or ResponseError(cause))
urllib3.exceptions.MaxRetryError: HTTPConnectionPool(host='192.168.1.251', port=1400): Max retries exceeded with url: /ZoneGroupTopology/Event (Caused by NewConnectionError('<urllib3.connection.HTTPConnection object at 0x7f8d7ed6afa0>: Failed to establish a new connection: [Errno 111] Connection refused'))

During handling of the above exception, another exception occurred:

Traceback (most recent call last):
  File "/usr/local/lib/python3.8/site-packages/pysonos/events.py", line 433, in _wrap
    method(*args, **kwargs)
  File "/usr/local/lib/python3.8/site-packages/pysonos/events_base.py", line 542, in renew
    return self._request(
  File "/usr/local/lib/python3.8/site-packages/pysonos/events.py", line 389, in _request
    response = requests.request(
  File "/usr/local/lib/python3.8/site-packages/requests/api.py", line 61, in request
    return session.request(method=method, url=url, **kwargs)
  File "/usr/local/lib/python3.8/site-packages/requests/sessions.py", line 530, in request
    resp = self.send(prep, **send_kwargs)
  File "/usr/local/lib/python3.8/site-packages/requests/sessions.py", line 643, in send
    r = adapter.send(request, **kwargs)
  File "/usr/local/lib/python3.8/site-packages/requests/adapters.py", line 516, in send
    raise ConnectionError(e, request=request)
requests.exceptions.ConnectionError: HTTPConnectionPool(host='192.168.1.251', port=1400): Max retries exceeded with url: /ZoneGroupTopology/Event (Caused by NewConnectionError('<urllib3.connection.HTTPConnection object at 0x7f8d7ed6afa0>: Failed to establish a new connection: [Errno 111] Connection refused'))
2020-11-11 03:21:15 ERROR (Thread-28) [pysonos.events] Exception received in Subscription.renew for Subscription to:
http://192.168.1.216:1400/MediaRenderer/AVTransport/Event, sid: uuid:RINCON_347E5C75D0DB01400_sub0000000014
Traceback (most recent call last):
  File "/usr/local/lib/python3.8/site-packages/urllib3/connection.py", line 159, in _new_conn
    conn = connection.create_connection(
  File "/usr/local/lib/python3.8/site-packages/urllib3/util/connection.py", line 84, in create_connection
    raise err
  File "/usr/local/lib/python3.8/site-packages/urllib3/util/connection.py", line 74, in create_connection
    sock.connect(sa)
ConnectionRefusedError: [Errno 111] Connection refused

During handling of the above exception, another exception occurred:

Traceback (most recent call last):
  File "/usr/local/lib/python3.8/site-packages/urllib3/connectionpool.py", line 670, in urlopen
    httplib_response = self._make_request(
  File "/usr/local/lib/python3.8/site-packages/urllib3/connectionpool.py", line 392, in _make_request
    conn.request(method, url, **httplib_request_kw)
  File "/usr/local/lib/python3.8/http/client.py", line 1255, in request
    self._send_request(method, url, body, headers, encode_chunked)
  File "/usr/local/lib/python3.8/http/client.py", line 1301, in _send_request
    self.endheaders(body, encode_chunked=encode_chunked)
  File "/usr/local/lib/python3.8/http/client.py", line 1250, in endheaders
    self._send_output(message_body, encode_chunked=encode_chunked)
  File "/usr/local/lib/python3.8/http/client.py", line 1010, in _send_output
    self.send(msg)
  File "/usr/local/lib/python3.8/http/client.py", line 950, in send
    self.connect()
  File "/usr/local/lib/python3.8/site-packages/urllib3/connection.py", line 187, in connect
    conn = self._new_conn()
  File "/usr/local/lib/python3.8/site-packages/urllib3/connection.py", line 171, in _new_conn
    raise NewConnectionError(
urllib3.exceptions.NewConnectionError: <urllib3.connection.HTTPConnection object at 0x7f8d868e8df0>: Failed to establish a new connection: [Errno 111] Connection refused

During handling of the above exception, another exception occurred:

Traceback (most recent call last):
  File "/usr/local/lib/python3.8/site-packages/requests/adapters.py", line 439, in send
    resp = conn.urlopen(
  File "/usr/local/lib/python3.8/site-packages/urllib3/connectionpool.py", line 726, in urlopen
    retries = retries.increment(
  File "/usr/local/lib/python3.8/site-packages/urllib3/util/retry.py", line 446, in increment
    raise MaxRetryError(_pool, url, error or ResponseError(cause))
urllib3.exceptions.MaxRetryError: HTTPConnectionPool(host='192.168.1.216', port=1400): Max retries exceeded with url: /MediaRenderer/AVTransport/Event (Caused by NewConnectionError('<urllib3.connection.HTTPConnection object at 0x7f8d868e8df0>: Failed to establish a new connection: [Errno 111] Connection refused'))

During handling of the above exception, another exception occurred:

Traceback (most recent call last):
  File "/usr/local/lib/python3.8/site-packages/pysonos/events.py", line 433, in _wrap
    method(*args, **kwargs)
  File "/usr/local/lib/python3.8/site-packages/pysonos/events_base.py", line 542, in renew
    return self._request(
  File "/usr/local/lib/python3.8/site-packages/pysonos/events.py", line 389, in _request
    response = requests.request(
  File "/usr/local/lib/python3.8/site-packages/requests/api.py", line 61, in request
    return session.request(method=method, url=url, **kwargs)
  File "/usr/local/lib/python3.8/site-packages/requests/sessions.py", line 530, in request
    resp = self.send(prep, **send_kwargs)
  File "/usr/local/lib/python3.8/site-packages/requests/sessions.py", line 643, in send
    r = adapter.send(request, **kwargs)
  File "/usr/local/lib/python3.8/site-packages/requests/adapters.py", line 516, in send
    raise ConnectionError(e, request=request)
requests.exceptions.ConnectionError: HTTPConnectionPool(host='192.168.1.216', port=1400): Max retries exceeded with url: /MediaRenderer/AVTransport/Event (Caused by NewConnectionError('<urllib3.connection.HTTPConnection object at 0x7f8d868e8df0>: Failed to establish a new connection: [Errno 111] Connection refused'))
2020-11-11 03:21:15 ERROR (Thread-29) [pysonos.events] Exception received in Subscription.renew for Subscription to:
http://192.168.1.253:1400/MediaRenderer/AVTransport/Event, sid: uuid:RINCON_347E5C03120001400_sub0000000018
Traceback (most recent call last):
  File "/usr/local/lib/python3.8/site-packages/urllib3/connection.py", line 159, in _new_conn
    conn = connection.create_connection(
  File "/usr/local/lib/python3.8/site-packages/urllib3/util/connection.py", line 84, in create_connection
    raise err
  File "/usr/local/lib/python3.8/site-packages/urllib3/util/connection.py", line 74, in create_connection
    sock.connect(sa)
ConnectionRefusedError: [Errno 111] Connection refused

During handling of the above exception, another exception occurred:

Traceback (most recent call last):
  File "/usr/local/lib/python3.8/site-packages/urllib3/connectionpool.py", line 670, in urlopen
    httplib_response = self._make_request(
  File "/usr/local/lib/python3.8/site-packages/urllib3/connectionpool.py", line 392, in _make_request
    conn.request(method, url, **httplib_request_kw)
  File "/usr/local/lib/python3.8/http/client.py", line 1255, in request
    self._send_request(method, url, body, headers, encode_chunked)
  File "/usr/local/lib/python3.8/http/client.py", line 1301, in _send_request
    self.endheaders(body, encode_chunked=encode_chunked)
  File "/usr/local/lib/python3.8/http/client.py", line 1250, in endheaders
    self._send_output(message_body, encode_chunked=encode_chunked)
  File "/usr/local/lib/python3.8/http/client.py", line 1010, in _send_output
    self.send(msg)
  File "/usr/local/lib/python3.8/http/client.py", line 950, in send
    self.connect()
  File "/usr/local/lib/python3.8/site-packages/urllib3/connection.py", line 187, in connect
    conn = self._new_conn()
  File "/usr/local/lib/python3.8/site-packages/urllib3/connection.py", line 171, in _new_conn
    raise NewConnectionError(
urllib3.exceptions.NewConnectionError: <urllib3.connection.HTTPConnection object at 0x7f8d7e7b1700>: Failed to establish a new connection: [Errno 111] Connection refused

During handling of the above exception, another exception occurred:

Traceback (most recent call last):
  File "/usr/local/lib/python3.8/site-packages/requests/adapters.py", line 439, in send
    resp = conn.urlopen(
  File "/usr/local/lib/python3.8/site-packages/urllib3/connectionpool.py", line 726, in urlopen
    retries = retries.increment(
  File "/usr/local/lib/python3.8/site-packages/urllib3/util/retry.py", line 446, in increment
    raise MaxRetryError(_pool, url, error or ResponseError(cause))
urllib3.exceptions.MaxRetryError: HTTPConnectionPool(host='192.168.1.253', port=1400): Max retries exceeded with url: /MediaRenderer/AVTransport/Event (Caused by NewConnectionError('<urllib3.connection.HTTPConnection object at 0x7f8d7e7b1700>: Failed to establish a new connection: [Errno 111] Connection refused'))

During handling of the above exception, another exception occurred:

Traceback (most recent call last):
  File "/usr/local/lib/python3.8/site-packages/pysonos/events.py", line 433, in _wrap
    method(*args, **kwargs)
  File "/usr/local/lib/python3.8/site-packages/pysonos/events_base.py", line 542, in renew
    return self._request(
  File "/usr/local/lib/python3.8/site-packages/pysonos/events.py", line 389, in _request
    response = requests.request(
  File "/usr/local/lib/python3.8/site-packages/requests/api.py", line 61, in request
    return session.request(method=method, url=url, **kwargs)
  File "/usr/local/lib/python3.8/site-packages/requests/sessions.py", line 530, in request
    resp = self.send(prep, **send_kwargs)
  File "/usr/local/lib/python3.8/site-packages/requests/sessions.py", line 643, in send
    r = adapter.send(request, **kwargs)
  File "/usr/local/lib/python3.8/site-packages/requests/adapters.py", line 516, in send
    raise ConnectionError(e, request=request)
requests.exceptions.ConnectionError: HTTPConnectionPool(host='192.168.1.253', port=1400): Max retries exceeded with url: /MediaRenderer/AVTransport/Event (Caused by NewConnectionError('<urllib3.connection.HTTPConnection object at 0x7f8d7e7b1700>: Failed to establish a new connection: [Errno 111] Connection refused'))
2020-11-11 03:21:15 ERROR (Thread-32) [pysonos.events] Exception received in Subscription.renew for Subscription to:
http://192.168.1.251:1400/MediaServer/ContentDirectory/Event, sid: uuid:RINCON_347E5C03124B01400_sub0000000029
Traceback (most recent call last):
  File "/usr/local/lib/python3.8/site-packages/urllib3/connection.py", line 159, in _new_conn
    conn = connection.create_connection(
  File "/usr/local/lib/python3.8/site-packages/urllib3/util/connection.py", line 84, in create_connection
    raise err
  File "/usr/local/lib/python3.8/site-packages/urllib3/util/connection.py", line 74, in create_connection
    sock.connect(sa)
ConnectionRefusedError: [Errno 111] Connection refused

During handling of the above exception, another exception occurred:

Traceback (most recent call last):
  File "/usr/local/lib/python3.8/site-packages/urllib3/connectionpool.py", line 670, in urlopen
    httplib_response = self._make_request(
  File "/usr/local/lib/python3.8/site-packages/urllib3/connectionpool.py", line 392, in _make_request
    conn.request(method, url, **httplib_request_kw)
  File "/usr/local/lib/python3.8/http/client.py", line 1255, in request
    self._send_request(method, url, body, headers, encode_chunked)
  File "/usr/local/lib/python3.8/http/client.py", line 1301, in _send_request
    self.endheaders(body, encode_chunked=encode_chunked)
  File "/usr/local/lib/python3.8/http/client.py", line 1250, in endheaders
    self._send_output(message_body, encode_chunked=encode_chunked)
  File "/usr/local/lib/python3.8/http/client.py", line 1010, in _send_output
    self.send(msg)
  File "/usr/local/lib/python3.8/http/client.py", line 950, in send
    self.connect()
  File "/usr/local/lib/python3.8/site-packages/urllib3/connection.py", line 187, in connect
    conn = self._new_conn()
  File "/usr/local/lib/python3.8/site-packages/urllib3/connection.py", line 171, in _new_conn
    raise NewConnectionError(
urllib3.exceptions.NewConnectionError: <urllib3.connection.HTTPConnection object at 0x7f8d7ced5550>: Failed to establish a new connection: [Errno 111] Connection refused

During handling of the above exception, another exception occurred:

Traceback (most recent call last):
  File "/usr/local/lib/python3.8/site-packages/requests/adapters.py", line 439, in send
    resp = conn.urlopen(
  File "/usr/local/lib/python3.8/site-packages/urllib3/connectionpool.py", line 726, in urlopen
    retries = retries.increment(
  File "/usr/local/lib/python3.8/site-packages/urllib3/util/retry.py", line 446, in increment
    raise MaxRetryError(_pool, url, error or ResponseError(cause))
urllib3.exceptions.MaxRetryError: HTTPConnectionPool(host='192.168.1.251', port=1400): Max retries exceeded with url: /MediaServer/ContentDirectory/Event (Caused by NewConnectionError('<urllib3.connection.HTTPConnection object at 0x7f8d7ced5550>: Failed to establish a new connection: [Errno 111] Connection refused'))

During handling of the above exception, another exception occurred:

Traceback (most recent call last):
  File "/usr/local/lib/python3.8/site-packages/pysonos/events.py", line 433, in _wrap
    method(*args, **kwargs)
  File "/usr/local/lib/python3.8/site-packages/pysonos/events_base.py", line 542, in renew
    return self._request(
  File "/usr/local/lib/python3.8/site-packages/pysonos/events.py", line 389, in _request
    response = requests.request(
  File "/usr/local/lib/python3.8/site-packages/requests/api.py", line 61, in request
    return session.request(method=method, url=url, **kwargs)
  File "/usr/local/lib/python3.8/site-packages/requests/sessions.py", line 530, in request
    resp = self.send(prep, **send_kwargs)
  File "/usr/local/lib/python3.8/site-packages/requests/sessions.py", line 643, in send
    r = adapter.send(request, **kwargs)
  File "/usr/local/lib/python3.8/site-packages/requests/adapters.py", line 516, in send
    raise ConnectionError(e, request=request)
requests.exceptions.ConnectionError: HTTPConnectionPool(host='192.168.1.251', port=1400): Max retries exceeded with url: /MediaServer/ContentDirectory/Event (Caused by NewConnectionError('<urllib3.connection.HTTPConnection object at 0x7f8d7ced5550>: Failed to establish a new connection: [Errno 111] Connection refused'))
2020-11-11 03:21:15 ERROR (Thread-33) [pysonos.events] Exception received in Subscription.renew for Subscription to:
http://192.168.1.216:1400/MediaRenderer/RenderingControl/Event, sid: uuid:RINCON_347E5C75D0DB01400_sub0000000015
Traceback (most recent call last):
  File "/usr/local/lib/python3.8/site-packages/urllib3/connection.py", line 159, in _new_conn
    conn = connection.create_connection(
  File "/usr/local/lib/python3.8/site-packages/urllib3/util/connection.py", line 84, in create_connection
    raise err
  File "/usr/local/lib/python3.8/site-packages/urllib3/util/connection.py", line 74, in create_connection
    sock.connect(sa)
ConnectionRefusedError: [Errno 111] Connection refused

During handling of the above exception, another exception occurred:

Traceback (most recent call last):
  File "/usr/local/lib/python3.8/site-packages/urllib3/connectionpool.py", line 670, in urlopen
    httplib_response = self._make_request(
  File "/usr/local/lib/python3.8/site-packages/urllib3/connectionpool.py", line 392, in _make_request
    conn.request(method, url, **httplib_request_kw)
  File "/usr/local/lib/python3.8/http/client.py", line 1255, in request
    self._send_request(method, url, body, headers, encode_chunked)
  File "/usr/local/lib/python3.8/http/client.py", line 1301, in _send_request
    self.endheaders(body, encode_chunked=encode_chunked)
  File "/usr/local/lib/python3.8/http/client.py", line 1250, in endheaders
    self._send_output(message_body, encode_chunked=encode_chunked)
  File "/usr/local/lib/python3.8/http/client.py", line 1010, in _send_output
    self.send(msg)
  File "/usr/local/lib/python3.8/http/client.py", line 950, in send
    self.connect()
  File "/usr/local/lib/python3.8/site-packages/urllib3/connection.py", line 187, in connect
    conn = self._new_conn()
  File "/usr/local/lib/python3.8/site-packages/urllib3/connection.py", line 171, in _new_conn
    raise NewConnectionError(
urllib3.exceptions.NewConnectionError: <urllib3.connection.HTTPConnection object at 0x7f8d7cfb9a00>: Failed to establish a new connection: [Errno 111] Connection refused

During handling of the above exception, another exception occurred:

Traceback (most recent call last):
  File "/usr/local/lib/python3.8/site-packages/requests/adapters.py", line 439, in send
    resp = conn.urlopen(
  File "/usr/local/lib/python3.8/site-packages/urllib3/connectionpool.py", line 726, in urlopen
    retries = retries.increment(
  File "/usr/local/lib/python3.8/site-packages/urllib3/util/retry.py", line 446, in increment
    raise MaxRetryError(_pool, url, error or ResponseError(cause))
urllib3.exceptions.MaxRetryError: HTTPConnectionPool(host='192.168.1.216', port=1400): Max retries exceeded with url: /MediaRenderer/RenderingControl/Event (Caused by NewConnectionError('<urllib3.connection.HTTPConnection object at 0x7f8d7cfb9a00>: Failed to establish a new connection: [Errno 111] Connection refused'))

During handling of the above exception, another exception occurred:

Traceback (most recent call last):
  File "/usr/local/lib/python3.8/site-packages/pysonos/events.py", line 433, in _wrap
    method(*args, **kwargs)
  File "/usr/local/lib/python3.8/site-packages/pysonos/events_base.py", line 542, in renew
    return self._request(
  File "/usr/local/lib/python3.8/site-packages/pysonos/events.py", line 389, in _request
    response = requests.request(
  File "/usr/local/lib/python3.8/site-packages/requests/api.py", line 61, in request
    return session.request(method=method, url=url, **kwargs)
  File "/usr/local/lib/python3.8/site-packages/requests/sessions.py", line 530, in request
    resp = self.send(prep, **send_kwargs)
  File "/usr/local/lib/python3.8/site-packages/requests/sessions.py", line 643, in send
    r = adapter.send(request, **kwargs)
  File "/usr/local/lib/python3.8/site-packages/requests/adapters.py", line 516, in send
    raise ConnectionError(e, request=request)
requests.exceptions.ConnectionError: HTTPConnectionPool(host='192.168.1.216', port=1400): Max retries exceeded with url: /MediaRenderer/RenderingControl/Event (Caused by NewConnectionError('<urllib3.connection.HTTPConnection object at 0x7f8d7cfb9a00>: Failed to establish a new connection: [Errno 111] Connection refused'))
2020-11-11 03:21:15 ERROR (Thread-31) [pysonos.events] Exception received in Subscription.renew for Subscription to:
http://192.168.1.209:1400/MediaRenderer/AVTransport/Event, sid: uuid:RINCON_949F3EDFC3C101400_sub0000000020
Traceback (most recent call last):
  File "/usr/local/lib/python3.8/site-packages/urllib3/connection.py", line 159, in _new_conn
    conn = connection.create_connection(
  File "/usr/local/lib/python3.8/site-packages/urllib3/util/connection.py", line 84, in create_connection
    raise err
  File "/usr/local/lib/python3.8/site-packages/urllib3/util/connection.py", line 74, in create_connection
    sock.connect(sa)
ConnectionRefusedError: [Errno 111] Connection refused

During handling of the above exception, another exception occurred:

Traceback (most recent call last):
  File "/usr/local/lib/python3.8/site-packages/urllib3/connectionpool.py", line 670, in urlopen
    httplib_response = self._make_request(
  File "/usr/local/lib/python3.8/site-packages/urllib3/connectionpool.py", line 392, in _make_request
    conn.request(method, url, **httplib_request_kw)
  File "/usr/local/lib/python3.8/http/client.py", line 1255, in request
    self._send_request(method, url, body, headers, encode_chunked)
  File "/usr/local/lib/python3.8/http/client.py", line 1301, in _send_request
    self.endheaders(body, encode_chunked=encode_chunked)
  File "/usr/local/lib/python3.8/http/client.py", line 1250, in endheaders
    self._send_output(message_body, encode_chunked=encode_chunked)
  File "/usr/local/lib/python3.8/http/client.py", line 1010, in _send_output
    self.send(msg)
  File "/usr/local/lib/python3.8/http/client.py", line 950, in send
    self.connect()
  File "/usr/local/lib/python3.8/site-packages/urllib3/connection.py", line 187, in connect
    conn = self._new_conn()
  File "/usr/local/lib/python3.8/site-packages/urllib3/connection.py", line 171, in _new_conn
    raise NewConnectionError(
urllib3.exceptions.NewConnectionError: <urllib3.connection.HTTPConnection object at 0x7f8d7e7b14c0>: Failed to establish a new connection: [Errno 111] Connection refused

During handling of the above exception, another exception occurred:

Traceback (most recent call last):
  File "/usr/local/lib/python3.8/site-packages/requests/adapters.py", line 439, in send
    resp = conn.urlopen(
  File "/usr/local/lib/python3.8/site-packages/urllib3/connectionpool.py", line 726, in urlopen
    retries = retries.increment(
  File "/usr/local/lib/python3.8/site-packages/urllib3/util/retry.py", line 446, in increment
    raise MaxRetryError(_pool, url, error or ResponseError(cause))
urllib3.exceptions.MaxRetryError: HTTPConnectionPool(host='192.168.1.209', port=1400): Max retries exceeded with url: /MediaRenderer/AVTransport/Event (Caused by NewConnectionError('<urllib3.connection.HTTPConnection object at 0x7f8d7e7b14c0>: Failed to establish a new connection: [Errno 111] Connection refused'))

During handling of the above exception, another exception occurred:

Traceback (most recent call last):
  File "/usr/local/lib/python3.8/site-packages/pysonos/events.py", line 433, in _wrap
    method(*args, **kwargs)
  File "/usr/local/lib/python3.8/site-packages/pysonos/events_base.py", line 542, in renew
    return self._request(
  File "/usr/local/lib/python3.8/site-packages/pysonos/events.py", line 389, in _request
    response = requests.request(
  File "/usr/local/lib/python3.8/site-packages/requests/api.py", line 61, in request
    return session.request(method=method, url=url, **kwargs)
  File "/usr/local/lib/python3.8/site-packages/requests/sessions.py", line 530, in request
    resp = self.send(prep, **send_kwargs)
  File "/usr/local/lib/python3.8/site-packages/requests/sessions.py", line 643, in send
    r = adapter.send(request, **kwargs)
  File "/usr/local/lib/python3.8/site-packages/requests/adapters.py", line 516, in send
    raise ConnectionError(e, request=request)
requests.exceptions.ConnectionError: HTTPConnectionPool(host='192.168.1.209', port=1400): Max retries exceeded with url: /MediaRenderer/AVTransport/Event (Caused by NewConnectionError('<urllib3.connection.HTTPConnection object at 0x7f8d7e7b14c0>: Failed to establish a new connection: [Errno 111] Connection refused'))
2020-11-11 03:21:15 ERROR (Thread-34) [pysonos.events] Exception received in Subscription.renew for Subscription to:
http://192.168.1.253:1400/MediaRenderer/RenderingControl/Event, sid: uuid:RINCON_347E5C03120001400_sub0000000019
Traceback (most recent call last):
  File "/usr/local/lib/python3.8/site-packages/urllib3/connection.py", line 159, in _new_conn
    conn = connection.create_connection(
  File "/usr/local/lib/python3.8/site-packages/urllib3/util/connection.py", line 84, in create_connection
    raise err
  File "/usr/local/lib/python3.8/site-packages/urllib3/util/connection.py", line 74, in create_connection
    sock.connect(sa)
ConnectionRefusedError: [Errno 111] Connection refused

During handling of the above exception, another exception occurred:

Traceback (most recent call last):
  File "/usr/local/lib/python3.8/site-packages/urllib3/connectionpool.py", line 670, in urlopen
    httplib_response = self._make_request(
  File "/usr/local/lib/python3.8/site-packages/urllib3/connectionpool.py", line 392, in _make_request
    conn.request(method, url, **httplib_request_kw)
  File "/usr/local/lib/python3.8/http/client.py", line 1255, in request
    self._send_request(method, url, body, headers, encode_chunked)
  File "/usr/local/lib/python3.8/http/client.py", line 1301, in _send_request
    self.endheaders(body, encode_chunked=encode_chunked)
  File "/usr/local/lib/python3.8/http/client.py", line 1250, in endheaders
    self._send_output(message_body, encode_chunked=encode_chunked)
  File "/usr/local/lib/python3.8/http/client.py", line 1010, in _send_output
    self.send(msg)
  File "/usr/local/lib/python3.8/http/client.py", line 950, in send
    self.connect()
  File "/usr/local/lib/python3.8/site-packages/urllib3/connection.py", line 187, in connect
    conn = self._new_conn()
  File "/usr/local/lib/python3.8/site-packages/urllib3/connection.py", line 171, in _new_conn
    raise NewConnectionError(
urllib3.exceptions.NewConnectionError: <urllib3.connection.HTTPConnection object at 0x7f8d88d032e0>: Failed to establish a new connection: [Errno 111] Connection refused

During handling of the above exception, another exception occurred:

Traceback (most recent call last):
  File "/usr/local/lib/python3.8/site-packages/requests/adapters.py", line 439, in send
    resp = conn.urlopen(
  File "/usr/local/lib/python3.8/site-packages/urllib3/connectionpool.py", line 726, in urlopen
    retries = retries.increment(
  File "/usr/local/lib/python3.8/site-packages/urllib3/util/retry.py", line 446, in increment
    raise MaxRetryError(_pool, url, error or ResponseError(cause))
urllib3.exceptions.MaxRetryError: HTTPConnectionPool(host='192.168.1.253', port=1400): Max retries exceeded with url: /MediaRenderer/RenderingControl/Event (Caused by NewConnectionError('<urllib3.connection.HTTPConnection object at 0x7f8d88d032e0>: Failed to establish a new connection: [Errno 111] Connection refused'))

During handling of the above exception, another exception occurred:

Traceback (most recent call last):
  File "/usr/local/lib/python3.8/site-packages/pysonos/events.py", line 433, in _wrap
    method(*args, **kwargs)
  File "/usr/local/lib/python3.8/site-packages/pysonos/events_base.py", line 542, in renew
    return self._request(
  File "/usr/local/lib/python3.8/site-packages/pysonos/events.py", line 389, in _request
    response = requests.request(
  File "/usr/local/lib/python3.8/site-packages/requests/api.py", line 61, in request
    return session.request(method=method, url=url, **kwargs)
  File "/usr/local/lib/python3.8/site-packages/requests/sessions.py", line 530, in request
    resp = self.send(prep, **send_kwargs)
  File "/usr/local/lib/python3.8/site-packages/requests/sessions.py", line 643, in send
    r = adapter.send(request, **kwargs)
  File "/usr/local/lib/python3.8/site-packages/requests/adapters.py", line 516, in send
    raise ConnectionError(e, request=request)
requests.exceptions.ConnectionError: HTTPConnectionPool(host='192.168.1.253', port=1400): Max retries exceeded with url: /MediaRenderer/RenderingControl/Event (Caused by NewConnectionError('<urllib3.connection.HTTPConnection object at 0x7f8d88d032e0>: Failed to establish a new connection: [Errno 111] Connection refused'))
2020-11-11 03:21:15 ERROR (Thread-38) [pysonos.events] Exception received in Subscription.renew for Subscription to:
http://192.168.1.253:1400/ZoneGroupTopology/Event, sid: uuid:RINCON_347E5C03120001400_sub0000000020
Traceback (most recent call last):
  File "/usr/local/lib/python3.8/site-packages/urllib3/connection.py", line 159, in _new_conn
    conn = connection.create_connection(
  File "/usr/local/lib/python3.8/site-packages/urllib3/util/connection.py", line 84, in create_connection
    raise err
  File "/usr/local/lib/python3.8/site-packages/urllib3/util/connection.py", line 74, in create_connection
    sock.connect(sa)
ConnectionRefusedError: [Errno 111] Connection refused

During handling of the above exception, another exception occurred:

Traceback (most recent call last):
  File "/usr/local/lib/python3.8/site-packages/urllib3/connectionpool.py", line 670, in urlopen
    httplib_response = self._make_request(
  File "/usr/local/lib/python3.8/site-packages/urllib3/connectionpool.py", line 392, in _make_request
    conn.request(method, url, **httplib_request_kw)
  File "/usr/local/lib/python3.8/http/client.py", line 1255, in request
    self._send_request(method, url, body, headers, encode_chunked)
  File "/usr/local/lib/python3.8/http/client.py", line 1301, in _send_request
    self.endheaders(body, encode_chunked=encode_chunked)
  File "/usr/local/lib/python3.8/http/client.py", line 1250, in endheaders
    self._send_output(message_body, encode_chunked=encode_chunked)
  File "/usr/local/lib/python3.8/http/client.py", line 1010, in _send_output
    self.send(msg)
  File "/usr/local/lib/python3.8/http/client.py", line 950, in send
    self.connect()
  File "/usr/local/lib/python3.8/site-packages/urllib3/connection.py", line 187, in connect
    conn = self._new_conn()
  File "/usr/local/lib/python3.8/site-packages/urllib3/connection.py", line 171, in _new_conn
    raise NewConnectionError(
urllib3.exceptions.NewConnectionError: <urllib3.connection.HTTPConnection object at 0x7f8d81b5e730>: Failed to establish a new connection: [Errno 111] Connection refused

During handling of the above exception, another exception occurred:

Traceback (most recent call last):
  File "/usr/local/lib/python3.8/site-packages/requests/adapters.py", line 439, in send
    resp = conn.urlopen(
  File "/usr/local/lib/python3.8/site-packages/urllib3/connectionpool.py", line 726, in urlopen
    retries = retries.increment(
  File "/usr/local/lib/python3.8/site-packages/urllib3/util/retry.py", line 446, in increment
    raise MaxRetryError(_pool, url, error or ResponseError(cause))
urllib3.exceptions.MaxRetryError: HTTPConnectionPool(host='192.168.1.253', port=1400): Max retries exceeded with url: /ZoneGroupTopology/Event (Caused by NewConnectionError('<urllib3.connection.HTTPConnection object at 0x7f8d81b5e730>: Failed to establish a new connection: [Errno 111] Connection refused'))

During handling of the above exception, another exception occurred:

Traceback (most recent call last):
  File "/usr/local/lib/python3.8/site-packages/pysonos/events.py", line 433, in _wrap
    method(*args, **kwargs)
  File "/usr/local/lib/python3.8/site-packages/pysonos/events_base.py", line 542, in renew
    return self._request(
  File "/usr/local/lib/python3.8/site-packages/pysonos/events.py", line 389, in _request
    response = requests.request(
  File "/usr/local/lib/python3.8/site-packages/requests/api.py", line 61, in request
    return session.request(method=method, url=url, **kwargs)
  File "/usr/local/lib/python3.8/site-packages/requests/sessions.py", line 530, in request
    resp = self.send(prep, **send_kwargs)
  File "/usr/local/lib/python3.8/site-packages/requests/sessions.py", line 643, in send
    r = adapter.send(request, **kwargs)
  File "/usr/local/lib/python3.8/site-packages/requests/adapters.py", line 516, in send
    raise ConnectionError(e, request=request)
requests.exceptions.ConnectionError: HTTPConnectionPool(host='192.168.1.253', port=1400): Max retries exceeded with url: /ZoneGroupTopology/Event (Caused by NewConnectionError('<urllib3.connection.HTTPConnection object at 0x7f8d81b5e730>: Failed to establish a new connection: [Errno 111] Connection refused'))
2020-11-11 03:21:15 ERROR (Thread-41) [pysonos.events] Exception received in Subscription.renew for Subscription to:
http://192.168.1.209:1400/MediaRenderer/RenderingControl/Event, sid: uuid:RINCON_949F3EDFC3C101400_sub0000000021
Traceback (most recent call last):
  File "/usr/local/lib/python3.8/site-packages/urllib3/connection.py", line 159, in _new_conn
    conn = connection.create_connection(
  File "/usr/local/lib/python3.8/site-packages/urllib3/util/connection.py", line 84, in create_connection
    raise err
  File "/usr/local/lib/python3.8/site-packages/urllib3/util/connection.py", line 74, in create_connection
    sock.connect(sa)
ConnectionRefusedError: [Errno 111] Connection refused

During handling of the above exception, another exception occurred:

Traceback (most recent call last):
  File "/usr/local/lib/python3.8/site-packages/urllib3/connectionpool.py", line 670, in urlopen
    httplib_response = self._make_request(
  File "/usr/local/lib/python3.8/site-packages/urllib3/connectionpool.py", line 392, in _make_request
    conn.request(method, url, **httplib_request_kw)
  File "/usr/local/lib/python3.8/http/client.py", line 1255, in request
    self._send_request(method, url, body, headers, encode_chunked)
  File "/usr/local/lib/python3.8/http/client.py", line 1301, in _send_request
    self.endheaders(body, encode_chunked=encode_chunked)
  File "/usr/local/lib/python3.8/http/client.py", line 1250, in endheaders
    self._send_output(message_body, encode_chunked=encode_chunked)
  File "/usr/local/lib/python3.8/http/client.py", line 1010, in _send_output
    self.send(msg)
  File "/usr/local/lib/python3.8/http/client.py", line 950, in send
    self.connect()
  File "/usr/local/lib/python3.8/site-packages/urllib3/connection.py", line 187, in connect
    conn = self._new_conn()
  File "/usr/local/lib/python3.8/site-packages/urllib3/connection.py", line 171, in _new_conn
    raise NewConnectionError(
urllib3.exceptions.NewConnectionError: <urllib3.connection.HTTPConnection object at 0x7f8d86779b80>: Failed to establish a new connection: [Errno 111] Connection refused

During handling of the above exception, another exception occurred:

Traceback (most recent call last):
  File "/usr/local/lib/python3.8/site-packages/requests/adapters.py", line 439, in send
    resp = conn.urlopen(
  File "/usr/local/lib/python3.8/site-packages/urllib3/connectionpool.py", line 726, in urlopen
    retries = retries.increment(
  File "/usr/local/lib/python3.8/site-packages/urllib3/util/retry.py", line 446, in increment
    raise MaxRetryError(_pool, url, error or ResponseError(cause))
urllib3.exceptions.MaxRetryError: HTTPConnectionPool(host='192.168.1.209', port=1400): Max retries exceeded with url: /MediaRenderer/RenderingControl/Event (Caused by NewConnectionError('<urllib3.connection.HTTPConnection object at 0x7f8d86779b80>: Failed to establish a new connection: [Errno 111] Connection refused'))

During handling of the above exception, another exception occurred:

Traceback (most recent call last):
  File "/usr/local/lib/python3.8/site-packages/pysonos/events.py", line 433, in _wrap
    method(*args, **kwargs)
  File "/usr/local/lib/python3.8/site-packages/pysonos/events_base.py", line 542, in renew
    return self._request(
  File "/usr/local/lib/python3.8/site-packages/pysonos/events.py", line 389, in _request
    response = requests.request(
  File "/usr/local/lib/python3.8/site-packages/requests/api.py", line 61, in request
    return session.request(method=method, url=url, **kwargs)
  File "/usr/local/lib/python3.8/site-packages/requests/sessions.py", line 530, in request
    resp = self.send(prep, **send_kwargs)
  File "/usr/local/lib/python3.8/site-packages/requests/sessions.py", line 643, in send
    r = adapter.send(request, **kwargs)
  File "/usr/local/lib/python3.8/site-packages/requests/adapters.py", line 516, in send
    raise ConnectionError(e, request=request)
requests.exceptions.ConnectionError: HTTPConnectionPool(host='192.168.1.209', port=1400): Max retries exceeded with url: /MediaRenderer/RenderingControl/Event (Caused by NewConnectionError('<urllib3.connection.HTTPConnection object at 0x7f8d86779b80>: Failed to establish a new connection: [Errno 111] Connection refused'))
2020-11-11 03:21:16 ERROR (Thread-43) [pysonos.events] Exception received in Subscription.renew for Subscription to:
http://192.168.1.209:1400/ZoneGroupTopology/Event, sid: uuid:RINCON_949F3EDFC3C101400_sub0000000022
Traceback (most recent call last):
  File "/usr/local/lib/python3.8/site-packages/urllib3/connection.py", line 159, in _new_conn
    conn = connection.create_connection(
  File "/usr/local/lib/python3.8/site-packages/urllib3/util/connection.py", line 84, in create_connection
    raise err
  File "/usr/local/lib/python3.8/site-packages/urllib3/util/connection.py", line 74, in create_connection
    sock.connect(sa)
ConnectionRefusedError: [Errno 111] Connection refused

During handling of the above exception, another exception occurred:

Traceback (most recent call last):
  File "/usr/local/lib/python3.8/site-packages/urllib3/connectionpool.py", line 670, in urlopen
    httplib_response = self._make_request(
  File "/usr/local/lib/python3.8/site-packages/urllib3/connectionpool.py", line 392, in _make_request
    conn.request(method, url, **httplib_request_kw)
  File "/usr/local/lib/python3.8/http/client.py", line 1255, in request
    self._send_request(method, url, body, headers, encode_chunked)
  File "/usr/local/lib/python3.8/http/client.py", line 1301, in _send_request
    self.endheaders(body, encode_chunked=encode_chunked)
  File "/usr/local/lib/python3.8/http/client.py", line 1250, in endheaders
    self._send_output(message_body, encode_chunked=encode_chunked)
  File "/usr/local/lib/python3.8/http/client.py", line 1010, in _send_output
    self.send(msg)
  File "/usr/local/lib/python3.8/http/client.py", line 950, in send
    self.connect()
  File "/usr/local/lib/python3.8/site-packages/urllib3/connection.py", line 187, in connect
    conn = self._new_conn()
  File "/usr/local/lib/python3.8/site-packages/urllib3/connection.py", line 171, in _new_conn
    raise NewConnectionError(
urllib3.exceptions.NewConnectionError: <urllib3.connection.HTTPConnection object at 0x7f8d89a1cfd0>: Failed to establish a new connection: [Errno 111] Connection refused

During handling of the above exception, another exception occurred:

Traceback (most recent call last):
  File "/usr/local/lib/python3.8/site-packages/requests/adapters.py", line 439, in send
    resp = conn.urlopen(
  File "/usr/local/lib/python3.8/site-packages/urllib3/connectionpool.py", line 726, in urlopen
    retries = retries.increment(
  File "/usr/local/lib/python3.8/site-packages/urllib3/util/retry.py", line 446, in increment
    raise MaxRetryError(_pool, url, error or ResponseError(cause))
urllib3.exceptions.MaxRetryError: HTTPConnectionPool(host='192.168.1.209', port=1400): Max retries exceeded with url: /ZoneGroupTopology/Event (Caused by NewConnectionError('<urllib3.connection.HTTPConnection object at 0x7f8d89a1cfd0>: Failed to establish a new connection: [Errno 111] Connection refused'))

During handling of the above exception, another exception occurred:

Traceback (most recent call last):
  File "/usr/local/lib/python3.8/site-packages/pysonos/events.py", line 433, in _wrap
    method(*args, **kwargs)
  File "/usr/local/lib/python3.8/site-packages/pysonos/events_base.py", line 542, in renew
    return self._request(
  File "/usr/local/lib/python3.8/site-packages/pysonos/events.py", line 389, in _request
    response = requests.request(
  File "/usr/local/lib/python3.8/site-packages/requests/api.py", line 61, in request
    return session.request(method=method, url=url, **kwargs)
  File "/usr/local/lib/python3.8/site-packages/requests/sessions.py", line 530, in request
    resp = self.send(prep, **send_kwargs)
  File "/usr/local/lib/python3.8/site-packages/requests/sessions.py", line 643, in send
    r = adapter.send(request, **kwargs)
  File "/usr/local/lib/python3.8/site-packages/requests/adapters.py", line 516, in send
    raise ConnectionError(e, request=request)
requests.exceptions.ConnectionError: HTTPConnectionPool(host='192.168.1.209', port=1400): Max retries exceeded with url: /ZoneGroupTopology/Event (Caused by NewConnectionError('<urllib3.connection.HTTPConnection object at 0x7f8d89a1cfd0>: Failed to establish a new connection: [Errno 111] Connection refused'))
2020-11-11 03:21:16 ERROR (Thread-44) [pysonos.events] Exception received in Subscription.renew for Subscription to:
http://192.168.1.209:1400/MediaServer/ContentDirectory/Event, sid: uuid:RINCON_949F3EDFC3C101400_sub0000000023
Traceback (most recent call last):
  File "/usr/local/lib/python3.8/site-packages/urllib3/connection.py", line 159, in _new_conn
    conn = connection.create_connection(
  File "/usr/local/lib/python3.8/site-packages/urllib3/util/connection.py", line 84, in create_connection
    raise err
  File "/usr/local/lib/python3.8/site-packages/urllib3/util/connection.py", line 74, in create_connection
    sock.connect(sa)
ConnectionRefusedError: [Errno 111] Connection refused

During handling of the above exception, another exception occurred:

Traceback (most recent call last):
  File "/usr/local/lib/python3.8/site-packages/urllib3/connectionpool.py", line 670, in urlopen
    httplib_response = self._make_request(
  File "/usr/local/lib/python3.8/site-packages/urllib3/connectionpool.py", line 392, in _make_request
    conn.request(method, url, **httplib_request_kw)
  File "/usr/local/lib/python3.8/http/client.py", line 1255, in request
    self._send_request(method, url, body, headers, encode_chunked)
  File "/usr/local/lib/python3.8/http/client.py", line 1301, in _send_request
    self.endheaders(body, encode_chunked=encode_chunked)
  File "/usr/local/lib/python3.8/http/client.py", line 1250, in endheaders
    self._send_output(message_body, encode_chunked=encode_chunked)
  File "/usr/local/lib/python3.8/http/client.py", line 1010, in _send_output
    self.send(msg)
  File "/usr/local/lib/python3.8/http/client.py", line 950, in send
    self.connect()
  File "/usr/local/lib/python3.8/site-packages/urllib3/connection.py", line 187, in connect
    conn = self._new_conn()
  File "/usr/local/lib/python3.8/site-packages/urllib3/connection.py", line 171, in _new_conn
    raise NewConnectionError(
urllib3.exceptions.NewConnectionError: <urllib3.connection.HTTPConnection object at 0x7f8d7ed7e820>: Failed to establish a new connection: [Errno 111] Connection refused

During handling of the above exception, another exception occurred:

Traceback (most recent call last):
  File "/usr/local/lib/python3.8/site-packages/requests/adapters.py", line 439, in send
    resp = conn.urlopen(
  File "/usr/local/lib/python3.8/site-packages/urllib3/connectionpool.py", line 726, in urlopen
    retries = retries.increment(
  File "/usr/local/lib/python3.8/site-packages/urllib3/util/retry.py", line 446, in increment
    raise MaxRetryError(_pool, url, error or ResponseError(cause))
urllib3.exceptions.MaxRetryError: HTTPConnectionPool(host='192.168.1.209', port=1400): Max retries exceeded with url: /MediaServer/ContentDirectory/Event (Caused by NewConnectionError('<urllib3.connection.HTTPConnection object at 0x7f8d7ed7e820>: Failed to establish a new connection: [Errno 111] Connection refused'))

During handling of the above exception, another exception occurred:

Traceback (most recent call last):
  File "/usr/local/lib/python3.8/site-packages/pysonos/events.py", line 433, in _wrap
    method(*args, **kwargs)
  File "/usr/local/lib/python3.8/site-packages/pysonos/events_base.py", line 542, in renew
    return self._request(
  File "/usr/local/lib/python3.8/site-packages/pysonos/events.py", line 389, in _request
    response = requests.request(
  File "/usr/local/lib/python3.8/site-packages/requests/api.py", line 61, in request
    return session.request(method=method, url=url, **kwargs)
  File "/usr/local/lib/python3.8/site-packages/requests/sessions.py", line 530, in request
    resp = self.send(prep, **send_kwargs)
  File "/usr/local/lib/python3.8/site-packages/requests/sessions.py", line 643, in send
    r = adapter.send(request, **kwargs)
  File "/usr/local/lib/python3.8/site-packages/requests/adapters.py", line 516, in send
    raise ConnectionError(e, request=request)
requests.exceptions.ConnectionError: HTTPConnectionPool(host='192.168.1.209', port=1400): Max retries exceeded with url: /MediaServer/ContentDirectory/Event (Caused by NewConnectionError('<urllib3.connection.HTTPConnection object at 0x7f8d7ed7e820>: Failed to establish a new connection: [Errno 111] Connection refused'))
2020-11-11 03:21:16 ERROR (Thread-46) [pysonos.events] Exception received in Subscription.renew for Subscription to:
http://192.168.1.216:1400/ZoneGroupTopology/Event, sid: uuid:RINCON_347E5C75D0DB01400_sub0000000016
Traceback (most recent call last):
  File "/usr/local/lib/python3.8/site-packages/urllib3/connection.py", line 159, in _new_conn
    conn = connection.create_connection(
  File "/usr/local/lib/python3.8/site-packages/urllib3/util/connection.py", line 84, in create_connection
    raise err
  File "/usr/local/lib/python3.8/site-packages/urllib3/util/connection.py", line 74, in create_connection
    sock.connect(sa)
ConnectionRefusedError: [Errno 111] Connection refused

During handling of the above exception, another exception occurred:

Traceback (most recent call last):
  File "/usr/local/lib/python3.8/site-packages/urllib3/connectionpool.py", line 670, in urlopen
    httplib_response = self._make_request(
  File "/usr/local/lib/python3.8/site-packages/urllib3/connectionpool.py", line 392, in _make_request
    conn.request(method, url, **httplib_request_kw)
  File "/usr/local/lib/python3.8/http/client.py", line 1255, in request
    self._send_request(method, url, body, headers, encode_chunked)
  File "/usr/local/lib/python3.8/http/client.py", line 1301, in _send_request
    self.endheaders(body, encode_chunked=encode_chunked)
  File "/usr/local/lib/python3.8/http/client.py", line 1250, in endheaders
    self._send_output(message_body, encode_chunked=encode_chunked)
  File "/usr/local/lib/python3.8/http/client.py", line 1010, in _send_output
    self.send(msg)
  File "/usr/local/lib/python3.8/http/client.py", line 950, in send
    self.connect()
  File "/usr/local/lib/python3.8/site-packages/urllib3/connection.py", line 187, in connect
    conn = self._new_conn()
  File "/usr/local/lib/python3.8/site-packages/urllib3/connection.py", line 171, in _new_conn
    raise NewConnectionError(
urllib3.exceptions.NewConnectionError: <urllib3.connection.HTTPConnection object at 0x7f8d86744490>: Failed to establish a new connection: [Errno 111] Connection refused

During handling of the above exception, another exception occurred:

Traceback (most recent call last):
  File "/usr/local/lib/python3.8/site-packages/requests/adapters.py", line 439, in send
    resp = conn.urlopen(
  File "/usr/local/lib/python3.8/site-packages/urllib3/connectionpool.py", line 726, in urlopen
    retries = retries.increment(
  File "/usr/local/lib/python3.8/site-packages/urllib3/util/retry.py", line 446, in increment
    raise MaxRetryError(_pool, url, error or ResponseError(cause))
urllib3.exceptions.MaxRetryError: HTTPConnectionPool(host='192.168.1.216', port=1400): Max retries exceeded with url: /ZoneGroupTopology/Event (Caused by NewConnectionError('<urllib3.connection.HTTPConnection object at 0x7f8d86744490>: Failed to establish a new connection: [Errno 111] Connection refused'))

During handling of the above exception, another exception occurred:

Traceback (most recent call last):
  File "/usr/local/lib/python3.8/site-packages/pysonos/events.py", line 433, in _wrap
    method(*args, **kwargs)
  File "/usr/local/lib/python3.8/site-packages/pysonos/events_base.py", line 542, in renew
    return self._request(
  File "/usr/local/lib/python3.8/site-packages/pysonos/events.py", line 389, in _request
    response = requests.request(
  File "/usr/local/lib/python3.8/site-packages/requests/api.py", line 61, in request
    return session.request(method=method, url=url, **kwargs)
  File "/usr/local/lib/python3.8/site-packages/requests/sessions.py", line 530, in request
    resp = self.send(prep, **send_kwargs)
  File "/usr/local/lib/python3.8/site-packages/requests/sessions.py", line 643, in send
    r = adapter.send(request, **kwargs)
  File "/usr/local/lib/python3.8/site-packages/requests/adapters.py", line 516, in send
    raise ConnectionError(e, request=request)
requests.exceptions.ConnectionError: HTTPConnectionPool(host='192.168.1.216', port=1400): Max retries exceeded with url: /ZoneGroupTopology/Event (Caused by NewConnectionError('<urllib3.connection.HTTPConnection object at 0x7f8d86744490>: Failed to establish a new connection: [Errno 111] Connection refused'))
2020-11-11 03:21:16 ERROR (Thread-39) [pysonos.events] Exception received in Subscription.renew for Subscription to:
http://192.168.1.253:1400/MediaServer/ContentDirectory/Event, sid: uuid:RINCON_347E5C03120001400_sub0000000021
Traceback (most recent call last):
  File "/usr/local/lib/python3.8/site-packages/urllib3/connection.py", line 159, in _new_conn
    conn = connection.create_connection(
  File "/usr/local/lib/python3.8/site-packages/urllib3/util/connection.py", line 84, in create_connection
    raise err
  File "/usr/local/lib/python3.8/site-packages/urllib3/util/connection.py", line 74, in create_connection
    sock.connect(sa)
ConnectionRefusedError: [Errno 111] Connection refused

During handling of the above exception, another exception occurred:

Traceback (most recent call last):
  File "/usr/local/lib/python3.8/site-packages/urllib3/connectionpool.py", line 670, in urlopen
    httplib_response = self._make_request(
  File "/usr/local/lib/python3.8/site-packages/urllib3/connectionpool.py", line 392, in _make_request
    conn.request(method, url, **httplib_request_kw)
  File "/usr/local/lib/python3.8/http/client.py", line 1255, in request
    self._send_request(method, url, body, headers, encode_chunked)
  File "/usr/local/lib/python3.8/http/client.py", line 1301, in _send_request
    self.endheaders(body, encode_chunked=encode_chunked)
  File "/usr/local/lib/python3.8/http/client.py", line 1250, in endheaders
    self._send_output(message_body, encode_chunked=encode_chunked)
  File "/usr/local/lib/python3.8/http/client.py", line 1010, in _send_output
    self.send(msg)
  File "/usr/local/lib/python3.8/http/client.py", line 950, in send
    self.connect()
  File "/usr/local/lib/python3.8/site-packages/urllib3/connection.py", line 187, in connect
    conn = self._new_conn()
  File "/usr/local/lib/python3.8/site-packages/urllib3/connection.py", line 171, in _new_conn
    raise NewConnectionError(
urllib3.exceptions.NewConnectionError: <urllib3.connection.HTTPConnection object at 0x7f8d86779a00>: Failed to establish a new connection: [Errno 111] Connection refused

During handling of the above exception, another exception occurred:

Traceback (most recent call last):
  File "/usr/local/lib/python3.8/site-packages/requests/adapters.py", line 439, in send
    resp = conn.urlopen(
  File "/usr/local/lib/python3.8/site-packages/urllib3/connectionpool.py", line 726, in urlopen
    retries = retries.increment(
  File "/usr/local/lib/python3.8/site-packages/urllib3/util/retry.py", line 446, in increment
    raise MaxRetryError(_pool, url, error or ResponseError(cause))
urllib3.exceptions.MaxRetryError: HTTPConnectionPool(host='192.168.1.253', port=1400): Max retries exceeded with url: /MediaServer/ContentDirectory/Event (Caused by NewConnectionError('<urllib3.connection.HTTPConnection object at 0x7f8d86779a00>: Failed to establish a new connection: [Errno 111] Connection refused'))

During handling of the above exception, another exception occurred:

Traceback (most recent call last):
  File "/usr/local/lib/python3.8/site-packages/pysonos/events.py", line 433, in _wrap
    method(*args, **kwargs)
  File "/usr/local/lib/python3.8/site-packages/pysonos/events_base.py", line 542, in renew
    return self._request(
  File "/usr/local/lib/python3.8/site-packages/pysonos/events.py", line 389, in _request
    response = requests.request(
  File "/usr/local/lib/python3.8/site-packages/requests/api.py", line 61, in request
    return session.request(method=method, url=url, **kwargs)
  File "/usr/local/lib/python3.8/site-packages/requests/sessions.py", line 530, in request
    resp = self.send(prep, **send_kwargs)
  File "/usr/local/lib/python3.8/site-packages/requests/sessions.py", line 643, in send
    r = adapter.send(request, **kwargs)
  File "/usr/local/lib/python3.8/site-packages/requests/adapters.py", line 516, in send
    raise ConnectionError(e, request=request)
requests.exceptions.ConnectionError: HTTPConnectionPool(host='192.168.1.253', port=1400): Max retries exceeded with url: /MediaServer/ContentDirectory/Event (Caused by NewConnectionError('<urllib3.connection.HTTPConnection object at 0x7f8d86779a00>: Failed to establish a new connection: [Errno 111] Connection refused'))
2020-11-11 03:21:16 ERROR (Thread-49) [pysonos.events] Exception received in Subscription.renew for Subscription to:
http://192.168.1.216:1400/MediaServer/ContentDirectory/Event, sid: uuid:RINCON_347E5C75D0DB01400_sub0000000017
Traceback (most recent call last):
  File "/usr/local/lib/python3.8/site-packages/urllib3/connection.py", line 159, in _new_conn
    conn = connection.create_connection(
  File "/usr/local/lib/python3.8/site-packages/urllib3/util/connection.py", line 84, in create_connection
    raise err
  File "/usr/local/lib/python3.8/site-packages/urllib3/util/connection.py", line 74, in create_connection
    sock.connect(sa)
ConnectionRefusedError: [Errno 111] Connection refused

During handling of the above exception, another exception occurred:

Traceback (most recent call last):
  File "/usr/local/lib/python3.8/site-packages/urllib3/connectionpool.py", line 670, in urlopen
    httplib_response = self._make_request(
  File "/usr/local/lib/python3.8/site-packages/urllib3/connectionpool.py", line 392, in _make_request
    conn.request(method, url, **httplib_request_kw)
  File "/usr/local/lib/python3.8/http/client.py", line 1255, in request
    self._send_request(method, url, body, headers, encode_chunked)
  File "/usr/local/lib/python3.8/http/client.py", line 1301, in _send_request
    self.endheaders(body, encode_chunked=encode_chunked)
  File "/usr/local/lib/python3.8/http/client.py", line 1250, in endheaders
    self._send_output(message_body, encode_chunked=encode_chunked)
  File "/usr/local/lib/python3.8/http/client.py", line 1010, in _send_output
    self.send(msg)
  File "/usr/local/lib/python3.8/http/client.py", line 950, in send
    self.connect()
  File "/usr/local/lib/python3.8/site-packages/urllib3/connection.py", line 187, in connect
    conn = self._new_conn()
  File "/usr/local/lib/python3.8/site-packages/urllib3/connection.py", line 171, in _new_conn
    raise NewConnectionError(
urllib3.exceptions.NewConnectionError: <urllib3.connection.HTTPConnection object at 0x7f8d868fe0d0>: Failed to establish a new connection: [Errno 111] Connection refused

During handling of the above exception, another exception occurred:

Traceback (most recent call last):
  File "/usr/local/lib/python3.8/site-packages/requests/adapters.py", line 439, in send
    resp = conn.urlopen(
  File "/usr/local/lib/python3.8/site-packages/urllib3/connectionpool.py", line 726, in urlopen
    retries = retries.increment(
  File "/usr/local/lib/python3.8/site-packages/urllib3/util/retry.py", line 446, in increment
    raise MaxRetryError(_pool, url, error or ResponseError(cause))
urllib3.exceptions.MaxRetryError: HTTPConnectionPool(host='192.168.1.216', port=1400): Max retries exceeded with url: /MediaServer/ContentDirectory/Event (Caused by NewConnectionError('<urllib3.connection.HTTPConnection object at 0x7f8d868fe0d0>: Failed to establish a new connection: [Errno 111] Connection refused'))

During handling of the above exception, another exception occurred:

Traceback (most recent call last):
  File "/usr/local/lib/python3.8/site-packages/pysonos/events.py", line 433, in _wrap
    method(*args, **kwargs)
  File "/usr/local/lib/python3.8/site-packages/pysonos/events_base.py", line 542, in renew
    return self._request(
  File "/usr/local/lib/python3.8/site-packages/pysonos/events.py", line 389, in _request
    response = requests.request(
  File "/usr/local/lib/python3.8/site-packages/requests/api.py", line 61, in request
    return session.request(method=method, url=url, **kwargs)
  File "/usr/local/lib/python3.8/site-packages/requests/sessions.py", line 530, in request
    resp = self.send(prep, **send_kwargs)
  File "/usr/local/lib/python3.8/site-packages/requests/sessions.py", line 643, in send
    r = adapter.send(request, **kwargs)
  File "/usr/local/lib/python3.8/site-packages/requests/adapters.py", line 516, in send
    raise ConnectionError(e, request=request)
requests.exceptions.ConnectionError: HTTPConnectionPool(host='192.168.1.216', port=1400): Max retries exceeded with url: /MediaServer/ContentDirectory/Event (Caused by NewConnectionError('<urllib3.connection.HTTPConnection object at 0x7f8d868fe0d0>: Failed to establish a new connection: [Errno 111] Connection refused'))
2020-11-11 03:45:15 WARNING (MainThread) [homeassistant.components.esphome] Error getting initial data for 192.168.1.252: Timeout while waiting for API response!
2020-11-11 04:12:00 ERROR (Recorder) [homeassistant.components.recorder.util] Error executing query: (sqlite3.DatabaseError) database disk image is malformed
[SQL: SELECT states.state_id AS states_state_id, states.domain AS states_domain, states.entity_id AS states_entity_id, states.state AS states_state, states.attributes AS states_attributes, states.event_id AS states_event_id, states.last_changed AS states_last_changed, states.last_updated AS states_last_updated, states.created AS states_created, states.old_state_id AS states_old_state_id 
FROM states ORDER BY states.last_updated ASC
 LIMIT ? OFFSET ?]
[parameters: (1, 0)]
(Background on this error at: http://sqlalche.me/e/13/4xp6)
2020-11-11 04:12:00 ERROR (Recorder) [homeassistant.components.recorder.util] Error executing query: (sqlite3.DatabaseError) database disk image is malformed
[SQL: SELECT states.state_id AS states_state_id, states.domain AS states_domain, states.entity_id AS states_entity_id, states.state AS states_state, states.attributes AS states_attributes, states.event_id AS states_event_id, states.last_changed AS states_last_changed, states.last_updated AS states_last_updated, states.created AS states_created, states.old_state_id AS states_old_state_id 
FROM states ORDER BY states.last_updated ASC
 LIMIT ? OFFSET ?]
[parameters: (1, 0)]
(Background on this error at: http://sqlalche.me/e/13/4xp6)
2020-11-11 04:12:00 ERROR (Recorder) [homeassistant.components.recorder.util] Error executing query: (sqlite3.DatabaseError) database disk image is malformed
[SQL: SELECT states.state_id AS states_state_id, states.domain AS states_domain, states.entity_id AS states_entity_id, states.state AS states_state, states.attributes AS states_attributes, states.event_id AS states_event_id, states.last_changed AS states_last_changed, states.last_updated AS states_last_updated, states.created AS states_created, states.old_state_id AS states_old_state_id 
FROM states ORDER BY states.last_updated ASC
 LIMIT ? OFFSET ?]
[parameters: (1, 0)]
(Background on this error at: http://sqlalche.me/e/13/4xp6)
2020-11-11 04:12:00 ERROR (Recorder) [homeassistant.components.recorder.util] Error executing query: (sqlite3.DatabaseError) database disk image is malformed
[SQL: SELECT states.state_id AS states_state_id, states.domain AS states_domain, states.entity_id AS states_entity_id, states.state AS states_state, states.attributes AS states_attributes, states.event_id AS states_event_id, states.last_changed AS states_last_changed, states.last_updated AS states_last_updated, states.created AS states_created, states.old_state_id AS states_old_state_id 
FROM states ORDER BY states.last_updated ASC
 LIMIT ? OFFSET ?]
[parameters: (1, 0)]
(Background on this error at: http://sqlalche.me/e/13/4xp6)
2020-11-11 04:12:01 WARNING (Recorder) [homeassistant.components.recorder.purge] Error purging history: (sqlite3.DatabaseError) database disk image is malformed
[SQL: SELECT states.state_id AS states_state_id, states.domain AS states_domain, states.entity_id AS states_entity_id, states.state AS states_state, states.attributes AS states_attributes, states.event_id AS states_event_id, states.last_changed AS states_last_changed, states.last_updated AS states_last_updated, states.created AS states_created, states.old_state_id AS states_old_state_id 
FROM states ORDER BY states.last_updated ASC
 LIMIT ? OFFSET ?]
[parameters: (1, 0)]
(Background on this error at: http://sqlalche.me/e/13/4xp6)
2020-11-11 07:14:14 WARNING (MainThread) [homeassistant.components.mobile_app.notify] Found duplicate device name iPhone
2020-11-11 07:14:14 WARNING (MainThread) [homeassistant.components.mobile_app.notify] Found duplicate device name iPhone
2020-11-11 07:14:14 WARNING (MainThread) [homeassistant.components.mobile_app.notify] Found duplicate device name iPhone
2020-11-11 07:14:14 WARNING (MainThread) [homeassistant.components.mobile_app.notify] Found duplicate device name iPhone
2020-11-11 07:31:07 WARNING (MainThread) [homeassistant.components.light.reproduce_state] The use of other attributes than device state attributes is deprecated and will be removed in a future release. Invalid attributes are ['brightness_pct', 'transition']. Read the logs for further details: https://www.home-assistant.io/integrations/scene/
2020-11-11 07:31:07 WARNING (MainThread) [homeassistant.components.light.reproduce_state] The use of other attributes than device state attributes is deprecated and will be removed in a future release. Invalid attributes are ['brightness_pct']. Read the logs for further details: https://www.home-assistant.io/integrations/scene/
2020-11-11 07:31:07 WARNING (MainThread) [homeassistant.components.light.reproduce_state] The use of other attributes than device state attributes is deprecated and will be removed in a future release. Invalid attributes are ['brightness_pct']. Read the logs for further details: https://www.home-assistant.io/integrations/scene/
2020-11-11 07:31:07 WARNING (MainThread) [homeassistant.components.light.reproduce_state] The use of other attributes than device state attributes is deprecated and will be removed in a future release. Invalid attributes are ['brightness_pct']. Read the logs for further details: https://www.home-assistant.io/integrations/scene/
2020-11-11 07:31:07 WARNING (MainThread) [homeassistant.components.light.reproduce_state] The use of other attributes than device state attributes is deprecated and will be removed in a future release. Invalid attributes are ['brightness_pct']. Read the logs for further details: https://www.home-assistant.io/integrations/scene/
2020-11-11 07:31:07 WARNING (MainThread) [homeassistant.components.light.reproduce_state] The use of other attributes than device state attributes is deprecated and will be removed in a future release. Invalid attributes are ['brightness_pct']. Read the logs for further details: https://www.home-assistant.io/integrations/scene/
2020-11-11 11:41:17 WARNING (MainThread) [homeassistant.components.esphome] Error getting initial data for 192.168.1.252: Timeout while waiting for API response!
2020-11-11 11:55:15 WARNING (MainThread) [homeassistant.components.esphome] Error getting initial data for 192.168.1.252: Timeout while waiting for API response!
2020-11-11 11:55:23 WARNING (MainThread) [homeassistant.components.esphome] Error getting initial data for 192.168.1.252: Timeout while waiting for API response!
2020-11-11 12:31:57 WARNING (MainThread) [homeassistant.components.esphome] Error getting initial data for 192.168.1.159: Timeout while waiting for API response!
2020-11-11 12:32:30 WARNING (MainThread) [homeassistant.components.esphome] Error getting initial data for 192.168.1.159: Timeout while waiting for API response!
2020-11-11 12:35:59 WARNING (MainThread) [homeassistant.components.esphome] Error getting initial data for 192.168.1.159: Timeout while waiting for API response!
2020-11-11 12:36:13 WARNING (MainThread) [homeassistant.components.esphome] Error getting initial data for 192.168.1.159: Timeout while waiting for API response!
2020-11-11 14:50:32 WARNING (MainThread) [homeassistant.components.esphome] Error getting initial data for 192.168.1.159: Timeout while waiting for API response!
2020-11-11 16:40:32 ERROR (MainThread) [homeassistant.components.automation.turn_outdoor_lights_on] turn outdoor lights on: Error executing script. Invalid data for call_service at pos 3: must contain at least one of entity_id, area_id.
2020-11-11 16:40:32 ERROR (MainThread) [homeassistant.components.automation.turn_outdoor_lights_on] While executing automation automation.turn_outdoor_lights_on
Traceback (most recent call last):
  File "/usr/local/lib/python3.8/site-packages/voluptuous/schema_builder.py", line 272, in __call__
    return self._compiled([], data)
  File "/usr/local/lib/python3.8/site-packages/voluptuous/schema_builder.py", line 817, in validate_callable
    return schema(data)
  File "/usr/src/homeassistant/homeassistant/helpers/config_validation.py", line 129, in validate
    raise vol.Invalid("must contain at least one of {}.".format(", ".join(keys)))
voluptuous.error.Invalid: must contain at least one of entity_id, area_id.

During handling of the above exception, another exception occurred:

Traceback (most recent call last):
  File "/usr/src/homeassistant/homeassistant/components/automation/__init__.py", line 426, in async_trigger
    await self.action_script.async_run(
  File "/usr/src/homeassistant/homeassistant/helpers/script.py", line 1010, in async_run
    await asyncio.shield(run.async_run())
  File "/usr/src/homeassistant/homeassistant/helpers/script.py", line 245, in async_run
    await self._async_step(log_exceptions=False)
  File "/usr/src/homeassistant/homeassistant/helpers/script.py", line 253, in _async_step
    await getattr(
  File "/usr/src/homeassistant/homeassistant/helpers/script.py", line 460, in _async_call_service_step
    await service_task
  File "/usr/src/homeassistant/homeassistant/core.py", line 1402, in async_call
    processed_data = handler.schema(service_data)
  File "/usr/local/lib/python3.8/site-packages/voluptuous/validators.py", line 218, in __call__
    return self._exec((Schema(val) for val in self.validators), v)
  File "/usr/local/lib/python3.8/site-packages/voluptuous/validators.py", line 340, in _exec
    raise e if self.msg is None else AllInvalid(self.msg, path=path)
  File "/usr/local/lib/python3.8/site-packages/voluptuous/validators.py", line 336, in _exec
    v = func(v)
  File "/usr/local/lib/python3.8/site-packages/voluptuous/schema_builder.py", line 276, in __call__
    raise er.MultipleInvalid([e])
voluptuous.error.MultipleInvalid: must contain at least one of entity_id, area_id.
2020-11-11 17:09:21 WARNING (MainThread) [homeassistant.components.mobile_app.notify] Found duplicate device name iPhone
2020-11-11 17:09:21 WARNING (MainThread) [homeassistant.components.mobile_app.notify] Found duplicate device name iPhone
2020-11-11 17:09:21 WARNING (MainThread) [homeassistant.components.mobile_app.notify] Found duplicate device name iPhone
2020-11-11 17:09:21 WARNING (MainThread) [homeassistant.components.mobile_app.notify] Found duplicate device name iPhone
2020-11-11 17:37:53 WARNING (MainThread) [homeassistant.components.mobile_app.notify] Found duplicate device name iPhone
2020-11-11 17:37:53 WARNING (MainThread) [homeassistant.components.mobile_app.notify] Found duplicate device name iPhone
2020-11-11 18:21:31 WARNING (MainThread) [homeassistant.components.esphome] Error getting initial data for 192.168.1.252: Timeout while waiting for API response!
2020-11-11 18:22:01 WARNING (MainThread) [homeassistant.components.esphome] Error getting initial data for 192.168.1.252: Timeout while waiting for API response!
2020-11-11 20:41:40 ERROR (MainThread) [homeassistant.components.august.activity] Request error trying to retrieve activity for house id 61fd9623-24f2-4ca9-8de4-1bd2c79e84c8: 
2020-11-12 00:44:21 WARNING (MainThread) [homeassistant.components.light.reproduce_state] Unable to find entity light.living_room_chand
2020-11-12 00:44:21 WARNING (MainThread) [homeassistant.components.light.reproduce_state] The use of other attributes than device state attributes is deprecated and will be removed in a future release. Invalid attributes are ['transition']. Read the logs for further details: https://www.home-assistant.io/integrations/scene/
2020-11-12 00:44:21 WARNING (MainThread) [homeassistant.components.light.reproduce_state] The use of other attributes than device state attributes is deprecated and will be removed in a future release. Invalid attributes are ['transition', 'brightness_pct']. Read the logs for further details: https://www.home-assistant.io/integrations/scene/
2020-11-12 00:44:21 WARNING (MainThread) [homeassistant.components.light.reproduce_state] The use of other attributes than device state attributes is deprecated and will be removed in a future release. Invalid attributes are ['transition', 'brightness_pct']. Read the logs for further details: https://www.home-assistant.io/integrations/scene/
2020-11-12 00:44:21 WARNING (MainThread) [homeassistant.components.light.reproduce_state] The use of other attributes than device state attributes is deprecated and will be removed in a future release. Invalid attributes are ['transition', 'brightness_pct']. Read the logs for further details: https://www.home-assistant.io/integrations/scene/
2020-11-12 00:46:25 WARNING (MainThread) [homeassistant.components.light.reproduce_state] The use of other attributes than device state attributes is deprecated and will be removed in a future release. Invalid attributes are ['brightness_pct', 'transition']. Read the logs for further details: https://www.home-assistant.io/integrations/scene/
2020-11-12 00:46:25 WARNING (MainThread) [homeassistant.components.light.reproduce_state] The use of other attributes than device state attributes is deprecated and will be removed in a future release. Invalid attributes are ['brightness_pct']. Read the logs for further details: https://www.home-assistant.io/integrations/scene/
2020-11-12 00:46:25 WARNING (MainThread) [homeassistant.components.light.reproduce_state] The use of other attributes than device state attributes is deprecated and will be removed in a future release. Invalid attributes are ['brightness_pct']. Read the logs for further details: https://www.home-assistant.io/integrations/scene/
2020-11-12 00:46:25 WARNING (MainThread) [homeassistant.components.light.reproduce_state] The use of other attributes than device state attributes is deprecated and will be removed in a future release. Invalid attributes are ['brightness_pct']. Read the logs for further details: https://www.home-assistant.io/integrations/scene/
2020-11-12 00:46:25 WARNING (MainThread) [homeassistant.components.light.reproduce_state] The use of other attributes than device state attributes is deprecated and will be removed in a future release. Invalid attributes are ['brightness_pct']. Read the logs for further details: https://www.home-assistant.io/integrations/scene/
2020-11-12 00:46:25 WARNING (MainThread) [homeassistant.components.light.reproduce_state] The use of other attributes than device state attributes is deprecated and will be removed in a future release. Invalid attributes are ['brightness_pct']. Read the logs for further details: https://www.home-assistant.io/integrations/scene/
2020-11-12 00:46:27 WARNING (MainThread) [homeassistant.components.light.reproduce_state] Unable to find entity light.living_room_chand
2020-11-12 00:46:27 WARNING (MainThread) [homeassistant.components.light.reproduce_state] The use of other attributes than device state attributes is deprecated and will be removed in a future release. Invalid attributes are ['transition']. Read the logs for further details: https://www.home-assistant.io/integrations/scene/
2020-11-12 00:46:27 WARNING (MainThread) [homeassistant.components.light.reproduce_state] The use of other attributes than device state attributes is deprecated and will be removed in a future release. Invalid attributes are ['transition', 'brightness_pct']. Read the logs for further details: https://www.home-assistant.io/integrations/scene/
2020-11-12 00:46:27 WARNING (MainThread) [homeassistant.components.light.reproduce_state] The use of other attributes than device state attributes is deprecated and will be removed in a future release. Invalid attributes are ['transition', 'brightness_pct']. Read the logs for further details: https://www.home-assistant.io/integrations/scene/
2020-11-12 00:46:27 WARNING (MainThread) [homeassistant.components.light.reproduce_state] The use of other attributes than device state attributes is deprecated and will be removed in a future release. Invalid attributes are ['transition', 'brightness_pct']. Read the logs for further details: https://www.home-assistant.io/integrations/scene/
2020-11-12 00:46:49 WARNING (MainThread) [homeassistant.components.light.reproduce_state] Unable to find entity light.living_room_chand
2020-11-12 00:46:49 WARNING (MainThread) [homeassistant.components.light.reproduce_state] The use of other attributes than device state attributes is deprecated and will be removed in a future release. Invalid attributes are ['transition']. Read the logs for further details: https://www.home-assistant.io/integrations/scene/
2020-11-12 00:46:49 WARNING (MainThread) [homeassistant.components.light.reproduce_state] The use of other attributes than device state attributes is deprecated and will be removed in a future release. Invalid attributes are ['transition', 'brightness_pct']. Read the logs for further details: https://www.home-assistant.io/integrations/scene/
2020-11-12 00:46:49 WARNING (MainThread) [homeassistant.components.light.reproduce_state] The use of other attributes than device state attributes is deprecated and will be removed in a future release. Invalid attributes are ['transition', 'brightness_pct']. Read the logs for further details: https://www.home-assistant.io/integrations/scene/
2020-11-12 00:46:49 WARNING (MainThread) [homeassistant.components.light.reproduce_state] The use of other attributes than device state attributes is deprecated and will be removed in a future release. Invalid attributes are ['transition', 'brightness_pct']. Read the logs for further details: https://www.home-assistant.io/integrations/scene/
2020-11-12 03:37:32 ERROR (MainThread) [pyhaversion] Timeout error fetching version information from PyPi, 
2020-11-12 03:37:32 WARNING (MainThread) [custom_components.breaking_changes] Could not get version data.
2020-11-12 04:12:00 ERROR (Recorder) [homeassistant.components.recorder.util] Error executing query: (sqlite3.DatabaseError) database disk image is malformed
[SQL: SELECT states.state_id AS states_state_id, states.domain AS states_domain, states.entity_id AS states_entity_id, states.state AS states_state, states.attributes AS states_attributes, states.event_id AS states_event_id, states.last_changed AS states_last_changed, states.last_updated AS states_last_updated, states.created AS states_created, states.old_state_id AS states_old_state_id 
FROM states ORDER BY states.last_updated ASC
 LIMIT ? OFFSET ?]
[parameters: (1, 0)]
(Background on this error at: http://sqlalche.me/e/13/4xp6)
2020-11-12 04:12:00 ERROR (Recorder) [homeassistant.components.recorder.util] Error executing query: (sqlite3.DatabaseError) database disk image is malformed
[SQL: SELECT states.state_id AS states_state_id, states.domain AS states_domain, states.entity_id AS states_entity_id, states.state AS states_state, states.attributes AS states_attributes, states.event_id AS states_event_id, states.last_changed AS states_last_changed, states.last_updated AS states_last_updated, states.created AS states_created, states.old_state_id AS states_old_state_id 
FROM states ORDER BY states.last_updated ASC
 LIMIT ? OFFSET ?]
[parameters: (1, 0)]
(Background on this error at: http://sqlalche.me/e/13/4xp6)
2020-11-12 04:12:00 ERROR (Recorder) [homeassistant.components.recorder.util] Error executing query: (sqlite3.DatabaseError) database disk image is malformed
[SQL: SELECT states.state_id AS states_state_id, states.domain AS states_domain, states.entity_id AS states_entity_id, states.state AS states_state, states.attributes AS states_attributes, states.event_id AS states_event_id, states.last_changed AS states_last_changed, states.last_updated AS states_last_updated, states.created AS states_created, states.old_state_id AS states_old_state_id 
FROM states ORDER BY states.last_updated ASC
 LIMIT ? OFFSET ?]
[parameters: (1, 0)]
(Background on this error at: http://sqlalche.me/e/13/4xp6)
2020-11-12 04:12:00 ERROR (Recorder) [homeassistant.components.recorder.util] Error executing query: (sqlite3.DatabaseError) database disk image is malformed
[SQL: SELECT states.state_id AS states_state_id, states.domain AS states_domain, states.entity_id AS states_entity_id, states.state AS states_state, states.attributes AS states_attributes, states.event_id AS states_event_id, states.last_changed AS states_last_changed, states.last_updated AS states_last_updated, states.created AS states_created, states.old_state_id AS states_old_state_id 
FROM states ORDER BY states.last_updated ASC
 LIMIT ? OFFSET ?]
[parameters: (1, 0)]
(Background on this error at: http://sqlalche.me/e/13/4xp6)
2020-11-12 04:12:00 WARNING (Recorder) [homeassistant.components.recorder.purge] Error purging history: (sqlite3.DatabaseError) database disk image is malformed
[SQL: SELECT states.state_id AS states_state_id, states.domain AS states_domain, states.entity_id AS states_entity_id, states.state AS states_state, states.attributes AS states_attributes, states.event_id AS states_event_id, states.last_changed AS states_last_changed, states.last_updated AS states_last_updated, states.created AS states_created, states.old_state_id AS states_old_state_id 
FROM states ORDER BY states.last_updated ASC
 LIMIT ? OFFSET ?]
[parameters: (1, 0)]
(Background on this error at: http://sqlalche.me/e/13/4xp6)
2020-11-12 07:31:18 WARNING (MainThread) [homeassistant.components.light.reproduce_state] The use of other attributes than device state attributes is deprecated and will be removed in a future release. Invalid attributes are ['brightness_pct', 'transition']. Read the logs for further details: https://www.home-assistant.io/integrations/scene/
2020-11-12 07:31:18 WARNING (MainThread) [homeassistant.components.light.reproduce_state] The use of other attributes than device state attributes is deprecated and will be removed in a future release. Invalid attributes are ['brightness_pct']. Read the logs for further details: https://www.home-assistant.io/integrations/scene/
2020-11-12 07:31:18 WARNING (MainThread) [homeassistant.components.light.reproduce_state] The use of other attributes than device state attributes is deprecated and will be removed in a future release. Invalid attributes are ['brightness_pct']. Read the logs for further details: https://www.home-assistant.io/integrations/scene/
2020-11-12 07:31:18 WARNING (MainThread) [homeassistant.components.light.reproduce_state] The use of other attributes than device state attributes is deprecated and will be removed in a future release. Invalid attributes are ['brightness_pct']. Read the logs for further details: https://www.home-assistant.io/integrations/scene/
2020-11-12 07:31:18 WARNING (MainThread) [homeassistant.components.light.reproduce_state] The use of other attributes than device state attributes is deprecated and will be removed in a future release. Invalid attributes are ['brightness_pct']. Read the logs for further details: https://www.home-assistant.io/integrations/scene/
2020-11-12 07:31:18 WARNING (MainThread) [homeassistant.components.light.reproduce_state] The use of other attributes than device state attributes is deprecated and will be removed in a future release. Invalid attributes are ['brightness_pct']. Read the logs for further details: https://www.home-assistant.io/integrations/scene/
2020-11-12 08:17:33 WARNING (MainThread) [homeassistant.components.mobile_app.notify] Found duplicate device name iPhone
2020-11-12 08:17:33 WARNING (MainThread) [homeassistant.components.mobile_app.notify] Found duplicate device name iPhone
2020-11-12 08:27:50 WARNING (MainThread) [homeassistant.components.mobile_app.notify] Found duplicate device name iPhone
2020-11-12 08:27:50 WARNING (MainThread) [homeassistant.components.mobile_app.notify] Found duplicate device name iPhone
2020-11-12 09:00:29 WARNING (MainThread) [homeassistant.components.light.reproduce_state] The use of other attributes than device state attributes is deprecated and will be removed in a future release. Invalid attributes are ['brightness_pct', 'transition']. Read the logs for further details: https://www.home-assistant.io/integrations/scene/
2020-11-12 09:00:29 WARNING (MainThread) [homeassistant.components.light.reproduce_state] The use of other attributes than device state attributes is deprecated and will be removed in a future release. Invalid attributes are ['brightness_pct']. Read the logs for further details: https://www.home-assistant.io/integrations/scene/
2020-11-12 09:00:29 WARNING (MainThread) [homeassistant.components.light.reproduce_state] The use of other attributes than device state attributes is deprecated and will be removed in a future release. Invalid attributes are ['brightness_pct']. Read the logs for further details: https://www.home-assistant.io/integrations/scene/
2020-11-12 09:00:29 WARNING (MainThread) [homeassistant.components.light.reproduce_state] The use of other attributes than device state attributes is deprecated and will be removed in a future release. Invalid attributes are ['brightness_pct']. Read the logs for further details: https://www.home-assistant.io/integrations/scene/
2020-11-12 09:00:29 WARNING (MainThread) [homeassistant.components.light.reproduce_state] The use of other attributes than device state attributes is deprecated and will be removed in a future release. Invalid attributes are ['brightness_pct']. Read the logs for further details: https://www.home-assistant.io/integrations/scene/
2020-11-12 09:00:29 WARNING (MainThread) [homeassistant.components.light.reproduce_state] The use of other attributes than device state attributes is deprecated and will be removed in a future release. Invalid attributes are ['brightness_pct']. Read the logs for further details: https://www.home-assistant.io/integrations/scene/
2020-11-12 16:39:47 ERROR (MainThread) [homeassistant.components.automation.turn_outdoor_lights_on] turn outdoor lights on: Error executing script. Invalid data for call_service at pos 3: must contain at least one of entity_id, area_id.
2020-11-12 16:39:47 ERROR (MainThread) [homeassistant.components.automation.turn_outdoor_lights_on] While executing automation automation.turn_outdoor_lights_on
Traceback (most recent call last):
  File "/usr/local/lib/python3.8/site-packages/voluptuous/schema_builder.py", line 272, in __call__
    return self._compiled([], data)
  File "/usr/local/lib/python3.8/site-packages/voluptuous/schema_builder.py", line 817, in validate_callable
    return schema(data)
  File "/usr/src/homeassistant/homeassistant/helpers/config_validation.py", line 129, in validate
    raise vol.Invalid("must contain at least one of {}.".format(", ".join(keys)))
voluptuous.error.Invalid: must contain at least one of entity_id, area_id.

During handling of the above exception, another exception occurred:

Traceback (most recent call last):
  File "/usr/src/homeassistant/homeassistant/components/automation/__init__.py", line 426, in async_trigger
    await self.action_script.async_run(
  File "/usr/src/homeassistant/homeassistant/helpers/script.py", line 1010, in async_run
    await asyncio.shield(run.async_run())
  File "/usr/src/homeassistant/homeassistant/helpers/script.py", line 245, in async_run
    await self._async_step(log_exceptions=False)
  File "/usr/src/homeassistant/homeassistant/helpers/script.py", line 253, in _async_step
    await getattr(
  File "/usr/src/homeassistant/homeassistant/helpers/script.py", line 460, in _async_call_service_step
    await service_task
  File "/usr/src/homeassistant/homeassistant/core.py", line 1402, in async_call
    processed_data = handler.schema(service_data)
  File "/usr/local/lib/python3.8/site-packages/voluptuous/validators.py", line 218, in __call__
    return self._exec((Schema(val) for val in self.validators), v)
  File "/usr/local/lib/python3.8/site-packages/voluptuous/validators.py", line 340, in _exec
    raise e if self.msg is None else AllInvalid(self.msg, path=path)
  File "/usr/local/lib/python3.8/site-packages/voluptuous/validators.py", line 336, in _exec
    v = func(v)
  File "/usr/local/lib/python3.8/site-packages/voluptuous/schema_builder.py", line 276, in __call__
    raise er.MultipleInvalid([e])
voluptuous.error.MultipleInvalid: must contain at least one of entity_id, area_id.
2020-11-12 17:11:33 WARNING (MainThread) [homeassistant.components.mobile_app.notify] Found duplicate device name iPhone
2020-11-12 17:11:33 WARNING (MainThread) [homeassistant.components.mobile_app.notify] Found duplicate device name iPhone
2020-11-12 17:11:33 WARNING (MainThread) [homeassistant.components.mobile_app.notify] Found duplicate device name iPhone
2020-11-12 17:11:33 WARNING (MainThread) [homeassistant.components.mobile_app.notify] Found duplicate device name iPhone
2020-11-12 17:42:08 WARNING (MainThread) [homeassistant.components.mobile_app.notify] Found duplicate device name iPhone
2020-11-12 17:42:08 WARNING (MainThread) [homeassistant.components.mobile_app.notify] Found duplicate device name iPhone
2020-11-12 23:40:44 WARNING (MainThread) [homeassistant.components.light.reproduce_state] Unable to find entity light.living_room_chand
2020-11-12 23:40:44 WARNING (MainThread) [homeassistant.components.light.reproduce_state] The use of other attributes than device state attributes is deprecated and will be removed in a future release. Invalid attributes are ['transition']. Read the logs for further details: https://www.home-assistant.io/integrations/scene/
2020-11-12 23:40:44 WARNING (MainThread) [homeassistant.components.light.reproduce_state] The use of other attributes than device state attributes is deprecated and will be removed in a future release. Invalid attributes are ['transition', 'brightness_pct']. Read the logs for further details: https://www.home-assistant.io/integrations/scene/
2020-11-12 23:40:44 WARNING (MainThread) [homeassistant.components.light.reproduce_state] The use of other attributes than device state attributes is deprecated and will be removed in a future release. Invalid attributes are ['transition', 'brightness_pct']. Read the logs for further details: https://www.home-assistant.io/integrations/scene/
2020-11-12 23:40:44 WARNING (MainThread) [homeassistant.components.light.reproduce_state] The use of other attributes than device state attributes is deprecated and will be removed in a future release. Invalid attributes are ['transition', 'brightness_pct']. Read the logs for further details: https://www.home-assistant.io/integrations/scene/
2020-11-12 23:44:40 WARNING (MainThread) [homeassistant.components.light.reproduce_state] Unable to find entity light.living_room_chand
2020-11-12 23:44:40 WARNING (MainThread) [homeassistant.components.light.reproduce_state] The use of other attributes than device state attributes is deprecated and will be removed in a future release. Invalid attributes are ['transition']. Read the logs for further details: https://www.home-assistant.io/integrations/scene/
2020-11-12 23:44:40 WARNING (MainThread) [homeassistant.components.light.reproduce_state] The use of other attributes than device state attributes is deprecated and will be removed in a future release. Invalid attributes are ['transition', 'brightness_pct']. Read the logs for further details: https://www.home-assistant.io/integrations/scene/
2020-11-12 23:44:40 WARNING (MainThread) [homeassistant.components.light.reproduce_state] The use of other attributes than device state attributes is deprecated and will be removed in a future release. Invalid attributes are ['transition', 'brightness_pct']. Read the logs for further details: https://www.home-assistant.io/integrations/scene/
2020-11-12 23:44:40 WARNING (MainThread) [homeassistant.components.light.reproduce_state] The use of other attributes than device state attributes is deprecated and will be removed in a future release. Invalid attributes are ['transition', 'brightness_pct']. Read the logs for further details: https://www.home-assistant.io/integrations/scene/
2020-11-13 00:32:27 ERROR (MainThread) [pyhaversion] Timeout error fetching version information from PyPi, 
2020-11-13 00:32:27 WARNING (MainThread) [custom_components.breaking_changes] Could not get version data.
2020-11-13 00:33:21 ERROR (MainThread) [snitun.multiplexer.core] Ping fails, no response from peer
2020-11-13 04:12:00 ERROR (Recorder) [homeassistant.components.recorder.util] Error executing query: (sqlite3.DatabaseError) database disk image is malformed
[SQL: SELECT states.state_id AS states_state_id, states.domain AS states_domain, states.entity_id AS states_entity_id, states.state AS states_state, states.attributes AS states_attributes, states.event_id AS states_event_id, states.last_changed AS states_last_changed, states.last_updated AS states_last_updated, states.created AS states_created, states.old_state_id AS states_old_state_id 
FROM states ORDER BY states.last_updated ASC
 LIMIT ? OFFSET ?]
[parameters: (1, 0)]
(Background on this error at: http://sqlalche.me/e/13/4xp6)
2020-11-13 04:12:00 ERROR (Recorder) [homeassistant.components.recorder.util] Error executing query: (sqlite3.DatabaseError) database disk image is malformed
[SQL: SELECT states.state_id AS states_state_id, states.domain AS states_domain, states.entity_id AS states_entity_id, states.state AS states_state, states.attributes AS states_attributes, states.event_id AS states_event_id, states.last_changed AS states_last_changed, states.last_updated AS states_last_updated, states.created AS states_created, states.old_state_id AS states_old_state_id 
FROM states ORDER BY states.last_updated ASC
 LIMIT ? OFFSET ?]
[parameters: (1, 0)]
(Background on this error at: http://sqlalche.me/e/13/4xp6)
2020-11-13 04:12:00 ERROR (Recorder) [homeassistant.components.recorder.util] Error executing query: (sqlite3.DatabaseError) database disk image is malformed
[SQL: SELECT states.state_id AS states_state_id, states.domain AS states_domain, states.entity_id AS states_entity_id, states.state AS states_state, states.attributes AS states_attributes, states.event_id AS states_event_id, states.last_changed AS states_last_changed, states.last_updated AS states_last_updated, states.created AS states_created, states.old_state_id AS states_old_state_id 
FROM states ORDER BY states.last_updated ASC
 LIMIT ? OFFSET ?]
[parameters: (1, 0)]
(Background on this error at: http://sqlalche.me/e/13/4xp6)
2020-11-13 04:12:00 ERROR (Recorder) [homeassistant.components.recorder.util] Error executing query: (sqlite3.DatabaseError) database disk image is malformed
[SQL: SELECT states.state_id AS states_state_id, states.domain AS states_domain, states.entity_id AS states_entity_id, states.state AS states_state, states.attributes AS states_attributes, states.event_id AS states_event_id, states.last_changed AS states_last_changed, states.last_updated AS states_last_updated, states.created AS states_created, states.old_state_id AS states_old_state_id 
FROM states ORDER BY states.last_updated ASC
 LIMIT ? OFFSET ?]
[parameters: (1, 0)]
(Background on this error at: http://sqlalche.me/e/13/4xp6)
2020-11-13 04:12:00 WARNING (Recorder) [homeassistant.components.recorder.purge] Error purging history: (sqlite3.DatabaseError) database disk image is malformed
[SQL: SELECT states.state_id AS states_state_id, states.domain AS states_domain, states.entity_id AS states_entity_id, states.state AS states_state, states.attributes AS states_attributes, states.event_id AS states_event_id, states.last_changed AS states_last_changed, states.last_updated AS states_last_updated, states.created AS states_created, states.old_state_id AS states_old_state_id 
FROM states ORDER BY states.last_updated ASC
 LIMIT ? OFFSET ?]
[parameters: (1, 0)]
(Background on this error at: http://sqlalche.me/e/13/4xp6)
2020-11-13 06:00:20 WARNING (MainThread) [homeassistant.components.mobile_app.notify] Found duplicate device name iPhone
2020-11-13 06:00:20 WARNING (MainThread) [homeassistant.components.mobile_app.notify] Found duplicate device name iPhone
2020-11-13 07:28:56 WARNING (MainThread) [homeassistant.components.light.reproduce_state] The use of other attributes than device state attributes is deprecated and will be removed in a future release. Invalid attributes are ['brightness_pct', 'transition']. Read the logs for further details: https://www.home-assistant.io/integrations/scene/
2020-11-13 07:28:56 WARNING (MainThread) [homeassistant.components.light.reproduce_state] The use of other attributes than device state attributes is deprecated and will be removed in a future release. Invalid attributes are ['brightness_pct']. Read the logs for further details: https://www.home-assistant.io/integrations/scene/
2020-11-13 07:28:56 WARNING (MainThread) [homeassistant.components.light.reproduce_state] The use of other attributes than device state attributes is deprecated and will be removed in a future release. Invalid attributes are ['brightness_pct']. Read the logs for further details: https://www.home-assistant.io/integrations/scene/
2020-11-13 07:28:56 WARNING (MainThread) [homeassistant.components.light.reproduce_state] The use of other attributes than device state attributes is deprecated and will be removed in a future release. Invalid attributes are ['brightness_pct']. Read the logs for further details: https://www.home-assistant.io/integrations/scene/
2020-11-13 07:28:56 WARNING (MainThread) [homeassistant.components.light.reproduce_state] The use of other attributes than device state attributes is deprecated and will be removed in a future release. Invalid attributes are ['brightness_pct']. Read the logs for further details: https://www.home-assistant.io/integrations/scene/
2020-11-13 07:28:56 WARNING (MainThread) [homeassistant.components.light.reproduce_state] The use of other attributes than device state attributes is deprecated and will be removed in a future release. Invalid attributes are ['brightness_pct']. Read the logs for further details: https://www.home-assistant.io/integrations/scene/
2020-11-13 13:09:49 WARNING (MainThread) [homeassistant.components.mobile_app.notify] Found duplicate device name iPhone
2020-11-13 13:09:49 WARNING (MainThread) [homeassistant.components.mobile_app.notify] Found duplicate device name iPhone
2020-11-13 13:09:49 WARNING (MainThread) [homeassistant.components.mobile_app.notify] Found duplicate device name iPhone
2020-11-13 13:09:49 WARNING (MainThread) [homeassistant.components.mobile_app.notify] Found duplicate device name iPhone
2020-11-13 15:01:37 WARNING (MainThread) [aiogithubapi] You need to call .set_last_commit to set this property
2020-11-13 15:35:35 WARNING (MainThread) [homeassistant.components.esphome] Error getting initial data for 192.168.1.159: Timeout while waiting for API response!
2020-11-13 16:30:33 ERROR (Thread-8712) [root] Uncaught thread exception
Traceback (most recent call last):
  File "/usr/local/lib/python3.8/threading.py", line 932, in _bootstrap_inner
    self.run()
  File "/usr/local/lib/python3.8/site-packages/speedtest.py", line 905, in run
    f = self._opener(request)
  File "/usr/local/lib/python3.8/urllib/request.py", line 525, in open
    response = self._open(req, data)
  File "/usr/local/lib/python3.8/urllib/request.py", line 542, in _open
    result = self._call_chain(self.handle_open, protocol, protocol +
  File "/usr/local/lib/python3.8/urllib/request.py", line 502, in _call_chain
    result = func(*args)
  File "/usr/local/lib/python3.8/site-packages/speedtest.py", line 537, in http_open
    return self.do_open(
  File "/usr/local/lib/python3.8/urllib/request.py", line 1354, in do_open
    r = h.getresponse()
  File "/usr/local/lib/python3.8/http/client.py", line 1347, in getresponse
    response.begin()
  File "/usr/local/lib/python3.8/http/client.py", line 307, in begin
    version, status, reason = self._read_status()
  File "/usr/local/lib/python3.8/http/client.py", line 289, in _read_status
    raise BadStatusLine(line)
http.client.BadStatusLine:  #Ì¹?Ìñàc]àö¤%ÇH)HTTP/1.1 200 OK

2020-11-13 16:30:34 ERROR (MainThread) [homeassistant.components.speedtestdotnet] Unexpected error fetching speedtestdotnet data: unsupported operand type(s) for +: 'int' and 'NoneType'
Traceback (most recent call last):
  File "/usr/src/homeassistant/homeassistant/helpers/update_coordinator.py", line 144, in async_refresh
    self.data = await self._async_update_data()
  File "/usr/src/homeassistant/homeassistant/helpers/update_coordinator.py", line 132, in _async_update_data
    return await self.update_method()
  File "/usr/src/homeassistant/homeassistant/components/speedtestdotnet/__init__.py", line 174, in async_update
    return await self.hass.async_add_executor_job(self.update_data)
  File "/usr/local/lib/python3.8/concurrent/futures/thread.py", line 57, in run
    result = self.fn(*self.args, **self.kwargs)
  File "/usr/src/homeassistant/homeassistant/components/speedtestdotnet/__init__.py", line 168, in update_data
    self.api.upload()
  File "/usr/local/lib/python3.8/site-packages/speedtest.py", line 1664, in upload
    self.results.bytes_sent = sum(finished)
TypeError: unsupported operand type(s) for +: 'int' and 'NoneType'
2020-11-13 16:39:03 ERROR (MainThread) [homeassistant.components.automation.turn_outdoor_lights_on] turn outdoor lights on: Error executing script. Invalid data for call_service at pos 3: must contain at least one of entity_id, area_id.
2020-11-13 16:39:03 ERROR (MainThread) [homeassistant.components.automation.turn_outdoor_lights_on] While executing automation automation.turn_outdoor_lights_on
Traceback (most recent call last):
  File "/usr/local/lib/python3.8/site-packages/voluptuous/schema_builder.py", line 272, in __call__
    return self._compiled([], data)
  File "/usr/local/lib/python3.8/site-packages/voluptuous/schema_builder.py", line 817, in validate_callable
    return schema(data)
  File "/usr/src/homeassistant/homeassistant/helpers/config_validation.py", line 129, in validate
    raise vol.Invalid("must contain at least one of {}.".format(", ".join(keys)))
voluptuous.error.Invalid: must contain at least one of entity_id, area_id.

During handling of the above exception, another exception occurred:

Traceback (most recent call last):
  File "/usr/src/homeassistant/homeassistant/components/automation/__init__.py", line 426, in async_trigger
    await self.action_script.async_run(
  File "/usr/src/homeassistant/homeassistant/helpers/script.py", line 1010, in async_run
    await asyncio.shield(run.async_run())
  File "/usr/src/homeassistant/homeassistant/helpers/script.py", line 245, in async_run
    await self._async_step(log_exceptions=False)
  File "/usr/src/homeassistant/homeassistant/helpers/script.py", line 253, in _async_step
    await getattr(
  File "/usr/src/homeassistant/homeassistant/helpers/script.py", line 460, in _async_call_service_step
    await service_task
  File "/usr/src/homeassistant/homeassistant/core.py", line 1402, in async_call
    processed_data = handler.schema(service_data)
  File "/usr/local/lib/python3.8/site-packages/voluptuous/validators.py", line 218, in __call__
    return self._exec((Schema(val) for val in self.validators), v)
  File "/usr/local/lib/python3.8/site-packages/voluptuous/validators.py", line 340, in _exec
    raise e if self.msg is None else AllInvalid(self.msg, path=path)
  File "/usr/local/lib/python3.8/site-packages/voluptuous/validators.py", line 336, in _exec
    v = func(v)
  File "/usr/local/lib/python3.8/site-packages/voluptuous/schema_builder.py", line 276, in __call__
    raise er.MultipleInvalid([e])
voluptuous.error.MultipleInvalid: must contain at least one of entity_id, area_id.
2020-11-13 18:01:53 WARNING (MainThread) [homeassistant.components.mobile_app.notify] Found duplicate device name iPhone
2020-11-13 18:01:53 WARNING (MainThread) [homeassistant.components.mobile_app.notify] Found duplicate device name iPhone
2020-11-13 20:17:34 WARNING (MainThread) [homeassistant.components.esphome] Error getting initial data for 192.168.1.159: Timeout while waiting for API response!
2020-11-13 20:34:07 WARNING (MainThread) [homeassistant.components.esphome] Error getting initial data for 192.168.1.159: Timeout while waiting for API response!
2020-11-13 20:38:44 WARNING (MainThread) [homeassistant.components.esphome] Error getting initial data for 192.168.1.159: Timeout while waiting for API response!
2020-11-13 20:41:18 WARNING (MainThread) [homeassistant.components.esphome] Error getting initial data for 192.168.1.159: Timeout while waiting for API response!
2020-11-13 20:43:05 WARNING (MainThread) [homeassistant.components.esphome] Error getting initial data for 192.168.1.159: Timeout while waiting for API response!
2020-11-13 21:03:34 WARNING (MainThread) [homeassistant.components.esphome] Error getting initial data for 192.168.1.159: Timeout while waiting for API response!
2020-11-13 21:04:15 WARNING (MainThread) [homeassistant.components.esphome] Error getting initial data for 192.168.1.159: Timeout while waiting for API response!
2020-11-13 21:24:59 WARNING (MainThread) [homeassistant.components.esphome] Error getting initial data for 192.168.1.159: Timeout while waiting for API response!
2020-11-13 21:46:18 WARNING (MainThread) [homeassistant.components.esphome] Error getting initial data for 192.168.1.159: Timeout while waiting for API response!
2020-11-13 21:56:26 WARNING (MainThread) [homeassistant.components.esphome] Error getting initial data for 192.168.1.159: Timeout while waiting for API response!
2020-11-13 21:58:28 WARNING (MainThread) [homeassistant.components.esphome] Error getting initial data for 192.168.1.159: Timeout while waiting for API response!
2020-11-13 22:15:20 WARNING (MainThread) [homeassistant.components.mobile_app.notify] Found duplicate device name iPhone
2020-11-13 22:15:20 WARNING (MainThread) [homeassistant.components.mobile_app.notify] Found duplicate device name iPhone
2020-11-13 22:15:20 WARNING (MainThread) [homeassistant.components.mobile_app.notify] Found duplicate device name iPhone
2020-11-13 22:15:20 WARNING (MainThread) [homeassistant.components.mobile_app.notify] Found duplicate device name iPhone
2020-11-13 22:16:57 WARNING (MainThread) [homeassistant.components.esphome] Error getting initial data for 192.168.1.159: Timeout while waiting for API response!
2020-11-13 23:24:43 WARNING (MainThread) [homeassistant.components.esphome] Error getting initial data for 192.168.1.159: Timeout while waiting for API response!
2020-11-13 23:40:55 WARNING (MainThread) [homeassistant.components.esphome] Error getting initial data for 192.168.1.159: Timeout while waiting for API response!
2020-11-13 23:43:13 WARNING (MainThread) [homeassistant.components.esphome] Error getting initial data for 192.168.1.159: Timeout while waiting for API response!
2020-11-14 01:11:22 WARNING (MainThread) [homeassistant.components.light.reproduce_state] Unable to find entity light.living_room_chand
2020-11-14 01:11:22 WARNING (MainThread) [homeassistant.components.light.reproduce_state] The use of other attributes than device state attributes is deprecated and will be removed in a future release. Invalid attributes are ['transition']. Read the logs for further details: https://www.home-assistant.io/integrations/scene/
2020-11-14 01:11:22 WARNING (MainThread) [homeassistant.components.light.reproduce_state] The use of other attributes than device state attributes is deprecated and will be removed in a future release. Invalid attributes are ['transition', 'brightness_pct']. Read the logs for further details: https://www.home-assistant.io/integrations/scene/
2020-11-14 01:11:22 WARNING (MainThread) [homeassistant.components.light.reproduce_state] The use of other attributes than device state attributes is deprecated and will be removed in a future release. Invalid attributes are ['transition', 'brightness_pct']. Read the logs for further details: https://www.home-assistant.io/integrations/scene/
2020-11-14 01:11:22 WARNING (MainThread) [homeassistant.components.light.reproduce_state] The use of other attributes than device state attributes is deprecated and will be removed in a future release. Invalid attributes are ['transition', 'brightness_pct']. Read the logs for further details: https://www.home-assistant.io/integrations/scene/
2020-11-14 01:11:44 WARNING (MainThread) [homeassistant.components.light.reproduce_state] Unable to find entity light.living_room_chand
2020-11-14 01:11:44 WARNING (MainThread) [homeassistant.components.light.reproduce_state] The use of other attributes than device state attributes is deprecated and will be removed in a future release. Invalid attributes are ['transition']. Read the logs for further details: https://www.home-assistant.io/integrations/scene/
2020-11-14 01:11:44 WARNING (MainThread) [homeassistant.components.light.reproduce_state] The use of other attributes than device state attributes is deprecated and will be removed in a future release. Invalid attributes are ['transition', 'brightness_pct']. Read the logs for further details: https://www.home-assistant.io/integrations/scene/
2020-11-14 01:11:44 WARNING (MainThread) [homeassistant.components.light.reproduce_state] The use of other attributes than device state attributes is deprecated and will be removed in a future release. Invalid attributes are ['transition', 'brightness_pct']. Read the logs for further details: https://www.home-assistant.io/integrations/scene/
2020-11-14 01:11:44 WARNING (MainThread) [homeassistant.components.light.reproduce_state] The use of other attributes than device state attributes is deprecated and will be removed in a future release. Invalid attributes are ['transition', 'brightness_pct']. Read the logs for further details: https://www.home-assistant.io/integrations/scene/
2020-11-14 04:12:00 ERROR (Recorder) [homeassistant.components.recorder.util] Error executing query: (sqlite3.DatabaseError) database disk image is malformed
[SQL: SELECT states.state_id AS states_state_id, states.domain AS states_domain, states.entity_id AS states_entity_id, states.state AS states_state, states.attributes AS states_attributes, states.event_id AS states_event_id, states.last_changed AS states_last_changed, states.last_updated AS states_last_updated, states.created AS states_created, states.old_state_id AS states_old_state_id 
FROM states ORDER BY states.last_updated ASC
 LIMIT ? OFFSET ?]
[parameters: (1, 0)]
(Background on this error at: http://sqlalche.me/e/13/4xp6)
2020-11-14 04:12:00 ERROR (Recorder) [homeassistant.components.recorder.util] Error executing query: (sqlite3.DatabaseError) database disk image is malformed
[SQL: SELECT states.state_id AS states_state_id, states.domain AS states_domain, states.entity_id AS states_entity_id, states.state AS states_state, states.attributes AS states_attributes, states.event_id AS states_event_id, states.last_changed AS states_last_changed, states.last_updated AS states_last_updated, states.created AS states_created, states.old_state_id AS states_old_state_id 
FROM states ORDER BY states.last_updated ASC
 LIMIT ? OFFSET ?]
[parameters: (1, 0)]
(Background on this error at: http://sqlalche.me/e/13/4xp6)
2020-11-14 04:12:00 ERROR (Recorder) [homeassistant.components.recorder.util] Error executing query: (sqlite3.DatabaseError) database disk image is malformed
[SQL: SELECT states.state_id AS states_state_id, states.domain AS states_domain, states.entity_id AS states_entity_id, states.state AS states_state, states.attributes AS states_attributes, states.event_id AS states_event_id, states.last_changed AS states_last_changed, states.last_updated AS states_last_updated, states.created AS states_created, states.old_state_id AS states_old_state_id 
FROM states ORDER BY states.last_updated ASC
 LIMIT ? OFFSET ?]
[parameters: (1, 0)]
(Background on this error at: http://sqlalche.me/e/13/4xp6)
2020-11-14 04:12:00 ERROR (Recorder) [homeassistant.components.recorder.util] Error executing query: (sqlite3.DatabaseError) database disk image is malformed
[SQL: SELECT states.state_id AS states_state_id, states.domain AS states_domain, states.entity_id AS states_entity_id, states.state AS states_state, states.attributes AS states_attributes, states.event_id AS states_event_id, states.last_changed AS states_last_changed, states.last_updated AS states_last_updated, states.created AS states_created, states.old_state_id AS states_old_state_id 
FROM states ORDER BY states.last_updated ASC
 LIMIT ? OFFSET ?]
[parameters: (1, 0)]
(Background on this error at: http://sqlalche.me/e/13/4xp6)
2020-11-14 04:12:00 WARNING (Recorder) [homeassistant.components.recorder.purge] Error purging history: (sqlite3.DatabaseError) database disk image is malformed
[SQL: SELECT states.state_id AS states_state_id, states.domain AS states_domain, states.entity_id AS states_entity_id, states.state AS states_state, states.attributes AS states_attributes, states.event_id AS states_event_id, states.last_changed AS states_last_changed, states.last_updated AS states_last_updated, states.created AS states_created, states.old_state_id AS states_old_state_id 
FROM states ORDER BY states.last_updated ASC
 LIMIT ? OFFSET ?]
[parameters: (1, 0)]
(Background on this error at: http://sqlalche.me/e/13/4xp6)
2020-11-14 07:38:32 WARNING (MainThread) [homeassistant.components.light.reproduce_state] The use of other attributes than device state attributes is deprecated and will be removed in a future release. Invalid attributes are ['brightness_pct', 'transition']. Read the logs for further details: https://www.home-assistant.io/integrations/scene/
2020-11-14 07:38:32 WARNING (MainThread) [homeassistant.components.light.reproduce_state] The use of other attributes than device state attributes is deprecated and will be removed in a future release. Invalid attributes are ['brightness_pct']. Read the logs for further details: https://www.home-assistant.io/integrations/scene/
2020-11-14 07:38:32 WARNING (MainThread) [homeassistant.components.light.reproduce_state] The use of other attributes than device state attributes is deprecated and will be removed in a future release. Invalid attributes are ['brightness_pct']. Read the logs for further details: https://www.home-assistant.io/integrations/scene/
2020-11-14 07:38:32 WARNING (MainThread) [homeassistant.components.light.reproduce_state] The use of other attributes than device state attributes is deprecated and will be removed in a future release. Invalid attributes are ['brightness_pct']. Read the logs for further details: https://www.home-assistant.io/integrations/scene/
2020-11-14 07:38:32 WARNING (MainThread) [homeassistant.components.light.reproduce_state] The use of other attributes than device state attributes is deprecated and will be removed in a future release. Invalid attributes are ['brightness_pct']. Read the logs for further details: https://www.home-assistant.io/integrations/scene/
2020-11-14 07:38:32 WARNING (MainThread) [homeassistant.components.light.reproduce_state] The use of other attributes than device state attributes is deprecated and will be removed in a future release. Invalid attributes are ['brightness_pct']. Read the logs for further details: https://www.home-assistant.io/integrations/scene/
2020-11-14 08:09:25 WARNING (MainThread) [homeassistant.components.mobile_app.notify] Found duplicate device name iPhone
2020-11-14 08:09:25 WARNING (MainThread) [homeassistant.components.mobile_app.notify] Found duplicate device name iPhone
2020-11-14 08:09:26 WARNING (MainThread) [homeassistant.components.mobile_app.notify] Found duplicate device name iPhone
2020-11-14 08:09:26 WARNING (MainThread) [homeassistant.components.mobile_app.notify] Found duplicate device name iPhone
2020-11-14 10:02:01 WARNING (MainThread) [homeassistant.helpers.entity] Updating state for zone.home (<class 'homeassistant.components.zone.Zone'>) took 0.652 seconds. Please create a bug report at https://github.com/home-assistant/core/issues?q=is%3Aopen+is%3Aissue+label%3A%22integration%3A+zone%22
2020-11-14 10:11:16 WARNING (MainThread) [homeassistant.components.light.reproduce_state] Unable to find entity light.living_room_chand
2020-11-14 10:11:16 WARNING (MainThread) [homeassistant.components.light.reproduce_state] The use of other attributes than device state attributes is deprecated and will be removed in a future release. Invalid attributes are ['transition']. Read the logs for further details: https://www.home-assistant.io/integrations/scene/
2020-11-14 10:11:16 WARNING (MainThread) [homeassistant.components.light.reproduce_state] The use of other attributes than device state attributes is deprecated and will be removed in a future release. Invalid attributes are ['transition', 'brightness_pct']. Read the logs for further details: https://www.home-assistant.io/integrations/scene/
2020-11-14 10:11:16 WARNING (MainThread) [homeassistant.components.light.reproduce_state] The use of other attributes than device state attributes is deprecated and will be removed in a future release. Invalid attributes are ['transition', 'brightness_pct']. Read the logs for further details: https://www.home-assistant.io/integrations/scene/
2020-11-14 10:11:16 WARNING (MainThread) [homeassistant.components.light.reproduce_state] The use of other attributes than device state attributes is deprecated and will be removed in a future release. Invalid attributes are ['transition', 'brightness_pct']. Read the logs for further details: https://www.home-assistant.io/integrations/scene/
2020-11-14 13:16:14 WARNING (MainThread) [homeassistant.components.mobile_app.notify] Found duplicate device name iPhone
2020-11-14 13:16:14 WARNING (MainThread) [homeassistant.components.mobile_app.notify] Found duplicate device name iPhone
2020-11-14 15:54:37 WARNING (MainThread) [homeassistant.components.esphome] Error getting initial data for 192.168.1.252: Timeout while waiting for API response!
2020-11-14 15:57:43 WARNING (MainThread) [homeassistant.components.esphome] Error getting initial data for 192.168.1.252: Timeout while waiting for API response!
2020-11-14 15:57:59 WARNING (MainThread) [homeassistant.components.esphome] Error getting initial data for 192.168.1.252: Timeout while waiting for API response!
2020-11-14 15:59:04 WARNING (MainThread) [homeassistant.components.esphome] Error getting initial data for 192.168.1.252: Timeout while waiting for API response!
2020-11-14 16:19:28 WARNING (MainThread) [homeassistant.components.mobile_app.notify] Found duplicate device name iPhone
2020-11-14 16:19:28 WARNING (MainThread) [homeassistant.components.mobile_app.notify] Found duplicate device name iPhone
2020-11-14 16:38:21 ERROR (MainThread) [homeassistant.components.automation.turn_outdoor_lights_on] turn outdoor lights on: Error executing script. Invalid data for call_service at pos 3: must contain at least one of entity_id, area_id.
2020-11-14 16:38:21 ERROR (MainThread) [homeassistant.components.automation.turn_outdoor_lights_on] While executing automation automation.turn_outdoor_lights_on
Traceback (most recent call last):
  File "/usr/local/lib/python3.8/site-packages/voluptuous/schema_builder.py", line 272, in __call__
    return self._compiled([], data)
  File "/usr/local/lib/python3.8/site-packages/voluptuous/schema_builder.py", line 817, in validate_callable
    return schema(data)
  File "/usr/src/homeassistant/homeassistant/helpers/config_validation.py", line 129, in validate
    raise vol.Invalid("must contain at least one of {}.".format(", ".join(keys)))
voluptuous.error.Invalid: must contain at least one of entity_id, area_id.

During handling of the above exception, another exception occurred:

Traceback (most recent call last):
  File "/usr/src/homeassistant/homeassistant/components/automation/__init__.py", line 426, in async_trigger
    await self.action_script.async_run(
  File "/usr/src/homeassistant/homeassistant/helpers/script.py", line 1010, in async_run
    await asyncio.shield(run.async_run())
  File "/usr/src/homeassistant/homeassistant/helpers/script.py", line 245, in async_run
    await self._async_step(log_exceptions=False)
  File "/usr/src/homeassistant/homeassistant/helpers/script.py", line 253, in _async_step
    await getattr(
  File "/usr/src/homeassistant/homeassistant/helpers/script.py", line 460, in _async_call_service_step
    await service_task
  File "/usr/src/homeassistant/homeassistant/core.py", line 1402, in async_call
    processed_data = handler.schema(service_data)
  File "/usr/local/lib/python3.8/site-packages/voluptuous/validators.py", line 218, in __call__
    return self._exec((Schema(val) for val in self.validators), v)
  File "/usr/local/lib/python3.8/site-packages/voluptuous/validators.py", line 340, in _exec
    raise e if self.msg is None else AllInvalid(self.msg, path=path)
  File "/usr/local/lib/python3.8/site-packages/voluptuous/validators.py", line 336, in _exec
    v = func(v)
  File "/usr/local/lib/python3.8/site-packages/voluptuous/schema_builder.py", line 276, in __call__
    raise er.MultipleInvalid([e])
voluptuous.error.MultipleInvalid: must contain at least one of entity_id, area_id.
2020-11-14 21:11:46 ERROR (MainThread) [pyhaversion] Timeout error fetching version information from PyPi, 
2020-11-14 21:11:46 WARNING (MainThread) [custom_components.breaking_changes] Could not get version data.
2020-11-14 23:48:24 WARNING (MainThread) [homeassistant.components.mobile_app.notify] Found duplicate device name iPhone
2020-11-14 23:48:24 WARNING (MainThread) [homeassistant.components.mobile_app.notify] Found duplicate device name iPhone
2020-11-15 00:14:46 WARNING (MainThread) [homeassistant.components.mobile_app.notify] Found duplicate device name iPhone
2020-11-15 00:14:46 WARNING (MainThread) [homeassistant.components.mobile_app.notify] Found duplicate device name iPhone
2020-11-15 00:48:32 WARNING (MainThread) [homeassistant.components.light.reproduce_state] Unable to find entity light.living_room_chand
2020-11-15 00:48:32 WARNING (MainThread) [homeassistant.components.light.reproduce_state] The use of other attributes than device state attributes is deprecated and will be removed in a future release. Invalid attributes are ['transition']. Read the logs for further details: https://www.home-assistant.io/integrations/scene/
2020-11-15 00:48:32 WARNING (MainThread) [homeassistant.components.light.reproduce_state] The use of other attributes than device state attributes is deprecated and will be removed in a future release. Invalid attributes are ['transition', 'brightness_pct']. Read the logs for further details: https://www.home-assistant.io/integrations/scene/
2020-11-15 00:48:32 WARNING (MainThread) [homeassistant.components.light.reproduce_state] The use of other attributes than device state attributes is deprecated and will be removed in a future release. Invalid attributes are ['transition', 'brightness_pct']. Read the logs for further details: https://www.home-assistant.io/integrations/scene/
2020-11-15 00:48:32 WARNING (MainThread) [homeassistant.components.light.reproduce_state] The use of other attributes than device state attributes is deprecated and will be removed in a future release. Invalid attributes are ['transition', 'brightness_pct']. Read the logs for further details: https://www.home-assistant.io/integrations/scene/
2020-11-15 04:12:00 ERROR (Recorder) [homeassistant.components.recorder.util] Error executing query: (sqlite3.DatabaseError) database disk image is malformed
[SQL: SELECT states.state_id AS states_state_id, states.domain AS states_domain, states.entity_id AS states_entity_id, states.state AS states_state, states.attributes AS states_attributes, states.event_id AS states_event_id, states.last_changed AS states_last_changed, states.last_updated AS states_last_updated, states.created AS states_created, states.old_state_id AS states_old_state_id 
FROM states ORDER BY states.last_updated ASC
 LIMIT ? OFFSET ?]
[parameters: (1, 0)]
(Background on this error at: http://sqlalche.me/e/13/4xp6)
2020-11-15 04:12:00 ERROR (Recorder) [homeassistant.components.recorder.util] Error executing query: (sqlite3.DatabaseError) database disk image is malformed
[SQL: SELECT states.state_id AS states_state_id, states.domain AS states_domain, states.entity_id AS states_entity_id, states.state AS states_state, states.attributes AS states_attributes, states.event_id AS states_event_id, states.last_changed AS states_last_changed, states.last_updated AS states_last_updated, states.created AS states_created, states.old_state_id AS states_old_state_id 
FROM states ORDER BY states.last_updated ASC
 LIMIT ? OFFSET ?]
[parameters: (1, 0)]
(Background on this error at: http://sqlalche.me/e/13/4xp6)
2020-11-15 04:12:00 ERROR (Recorder) [homeassistant.components.recorder.util] Error executing query: (sqlite3.DatabaseError) database disk image is malformed
[SQL: SELECT states.state_id AS states_state_id, states.domain AS states_domain, states.entity_id AS states_entity_id, states.state AS states_state, states.attributes AS states_attributes, states.event_id AS states_event_id, states.last_changed AS states_last_changed, states.last_updated AS states_last_updated, states.created AS states_created, states.old_state_id AS states_old_state_id 
FROM states ORDER BY states.last_updated ASC
 LIMIT ? OFFSET ?]
[parameters: (1, 0)]
(Background on this error at: http://sqlalche.me/e/13/4xp6)
2020-11-15 04:12:00 ERROR (Recorder) [homeassistant.components.recorder.util] Error executing query: (sqlite3.DatabaseError) database disk image is malformed
[SQL: SELECT states.state_id AS states_state_id, states.domain AS states_domain, states.entity_id AS states_entity_id, states.state AS states_state, states.attributes AS states_attributes, states.event_id AS states_event_id, states.last_changed AS states_last_changed, states.last_updated AS states_last_updated, states.created AS states_created, states.old_state_id AS states_old_state_id 
FROM states ORDER BY states.last_updated ASC
 LIMIT ? OFFSET ?]
[parameters: (1, 0)]
(Background on this error at: http://sqlalche.me/e/13/4xp6)
2020-11-15 04:12:01 WARNING (Recorder) [homeassistant.components.recorder.purge] Error purging history: (sqlite3.DatabaseError) database disk image is malformed
[SQL: SELECT states.state_id AS states_state_id, states.domain AS states_domain, states.entity_id AS states_entity_id, states.state AS states_state, states.attributes AS states_attributes, states.event_id AS states_event_id, states.last_changed AS states_last_changed, states.last_updated AS states_last_updated, states.created AS states_created, states.old_state_id AS states_old_state_id 
FROM states ORDER BY states.last_updated ASC
 LIMIT ? OFFSET ?]
[parameters: (1, 0)]
(Background on this error at: http://sqlalche.me/e/13/4xp6)
2020-11-15 07:01:50 ERROR (MainThread) [homeassistant] Error doing job: Task exception was never retrieved
Traceback (most recent call last):
  File "/config/custom_components/hacs/hacsbase/hacs.py", line 287, in recurring_tasks_installed
    await self.data.async_write()
  File "/config/custom_components/hacs/hacsbase/data.py", line 50, in async_write
    await self.queue.execute()
  File "/usr/local/lib/python3.8/site-packages/queueman/manager.py", line 41, in execute
    raise QueueManagerExecutionStillInProgress
queueman.exceptions.QueueManagerExecutionStillInProgress
2020-11-15 08:36:40 WARNING (MainThread) [homeassistant.components.light.reproduce_state] The use of other attributes than device state attributes is deprecated and will be removed in a future release. Invalid attributes are ['brightness_pct', 'transition']. Read the logs for further details: https://www.home-assistant.io/integrations/scene/
2020-11-15 08:36:40 WARNING (MainThread) [homeassistant.components.light.reproduce_state] The use of other attributes than device state attributes is deprecated and will be removed in a future release. Invalid attributes are ['brightness_pct']. Read the logs for further details: https://www.home-assistant.io/integrations/scene/
2020-11-15 08:36:40 WARNING (MainThread) [homeassistant.components.light.reproduce_state] The use of other attributes than device state attributes is deprecated and will be removed in a future release. Invalid attributes are ['brightness_pct']. Read the logs for further details: https://www.home-assistant.io/integrations/scene/
2020-11-15 08:36:40 WARNING (MainThread) [homeassistant.components.light.reproduce_state] The use of other attributes than device state attributes is deprecated and will be removed in a future release. Invalid attributes are ['brightness_pct']. Read the logs for further details: https://www.home-assistant.io/integrations/scene/
2020-11-15 08:36:40 WARNING (MainThread) [homeassistant.components.light.reproduce_state] The use of other attributes than device state attributes is deprecated and will be removed in a future release. Invalid attributes are ['brightness_pct']. Read the logs for further details: https://www.home-assistant.io/integrations/scene/
2020-11-15 08:36:40 WARNING (MainThread) [homeassistant.components.light.reproduce_state] The use of other attributes than device state attributes is deprecated and will be removed in a future release. Invalid attributes are ['brightness_pct']. Read the logs for further details: https://www.home-assistant.io/integrations/scene/
2020-11-15 11:06:20 WARNING (MainThread) [homeassistant.components.mobile_app.notify] Found duplicate device name iPhone
2020-11-15 11:06:20 WARNING (MainThread) [homeassistant.components.mobile_app.notify] Found duplicate device name iPhone
2020-11-15 16:37:40 ERROR (MainThread) [homeassistant.components.automation.turn_outdoor_lights_on] turn outdoor lights on: Error executing script. Invalid data for call_service at pos 3: must contain at least one of entity_id, area_id.
2020-11-15 16:37:40 ERROR (MainThread) [homeassistant.components.automation.turn_outdoor_lights_on] While executing automation automation.turn_outdoor_lights_on
Traceback (most recent call last):
  File "/usr/local/lib/python3.8/site-packages/voluptuous/schema_builder.py", line 272, in __call__
    return self._compiled([], data)
  File "/usr/local/lib/python3.8/site-packages/voluptuous/schema_builder.py", line 817, in validate_callable
    return schema(data)
  File "/usr/src/homeassistant/homeassistant/helpers/config_validation.py", line 129, in validate
    raise vol.Invalid("must contain at least one of {}.".format(", ".join(keys)))
voluptuous.error.Invalid: must contain at least one of entity_id, area_id.

During handling of the above exception, another exception occurred:

Traceback (most recent call last):
  File "/usr/src/homeassistant/homeassistant/components/automation/__init__.py", line 426, in async_trigger
    await self.action_script.async_run(
  File "/usr/src/homeassistant/homeassistant/helpers/script.py", line 1010, in async_run
    await asyncio.shield(run.async_run())
  File "/usr/src/homeassistant/homeassistant/helpers/script.py", line 245, in async_run
    await self._async_step(log_exceptions=False)
  File "/usr/src/homeassistant/homeassistant/helpers/script.py", line 253, in _async_step
    await getattr(
  File "/usr/src/homeassistant/homeassistant/helpers/script.py", line 460, in _async_call_service_step
    await service_task
  File "/usr/src/homeassistant/homeassistant/core.py", line 1402, in async_call
    processed_data = handler.schema(service_data)
  File "/usr/local/lib/python3.8/site-packages/voluptuous/validators.py", line 218, in __call__
    return self._exec((Schema(val) for val in self.validators), v)
  File "/usr/local/lib/python3.8/site-packages/voluptuous/validators.py", line 340, in _exec
    raise e if self.msg is None else AllInvalid(self.msg, path=path)
  File "/usr/local/lib/python3.8/site-packages/voluptuous/validators.py", line 336, in _exec
    v = func(v)
  File "/usr/local/lib/python3.8/site-packages/voluptuous/schema_builder.py", line 276, in __call__
    raise er.MultipleInvalid([e])
voluptuous.error.MultipleInvalid: must contain at least one of entity_id, area_id.
2020-11-15 17:46:12 WARNING (MainThread) [homeassistant.components.mobile_app.notify] Found duplicate device name iPhone
2020-11-15 17:46:12 WARNING (MainThread) [homeassistant.components.mobile_app.notify] Found duplicate device name iPhone
2020-11-15 19:44:41 WARNING (MainThread) [homeassistant.components.mobile_app.notify] Found duplicate device name iPhone
2020-11-15 19:44:41 WARNING (MainThread) [homeassistant.components.mobile_app.notify] Found duplicate device name iPhone
2020-11-15 20:41:10 WARNING (MainThread) [homeassistant.components.light.reproduce_state] The use of other attributes than device state attributes is deprecated and will be removed in a future release. Invalid attributes are ['brightness_pct', 'transition']. Read the logs for further details: https://www.home-assistant.io/integrations/scene/
2020-11-15 20:41:10 WARNING (MainThread) [homeassistant.components.light.reproduce_state] The use of other attributes than device state attributes is deprecated and will be removed in a future release. Invalid attributes are ['transition']. Read the logs for further details: https://www.home-assistant.io/integrations/scene/
2020-11-15 20:41:10 WARNING (MainThread) [homeassistant.components.light.reproduce_state] The use of other attributes than device state attributes is deprecated and will be removed in a future release. Invalid attributes are ['brightness_pct', 'transition']. Read the logs for further details: https://www.home-assistant.io/integrations/scene/
2020-11-15 20:41:10 WARNING (MainThread) [homeassistant.components.light.reproduce_state] The use of other attributes than device state attributes is deprecated and will be removed in a future release. Invalid attributes are ['transition']. Read the logs for further details: https://www.home-assistant.io/integrations/scene/
2020-11-15 20:41:10 WARNING (MainThread) [homeassistant.components.light.reproduce_state] The use of other attributes than device state attributes is deprecated and will be removed in a future release. Invalid attributes are ['transition']. Read the logs for further details: https://www.home-assistant.io/integrations/scene/
2020-11-15 23:01:46 WARNING (MainThread) [homeassistant.components.light.reproduce_state] Unable to find entity light.living_room_chand
2020-11-15 23:01:46 WARNING (MainThread) [homeassistant.components.light.reproduce_state] The use of other attributes than device state attributes is deprecated and will be removed in a future release. Invalid attributes are ['transition']. Read the logs for further details: https://www.home-assistant.io/integrations/scene/
2020-11-15 23:01:46 WARNING (MainThread) [homeassistant.components.light.reproduce_state] The use of other attributes than device state attributes is deprecated and will be removed in a future release. Invalid attributes are ['transition', 'brightness_pct']. Read the logs for further details: https://www.home-assistant.io/integrations/scene/
2020-11-15 23:01:46 WARNING (MainThread) [homeassistant.components.light.reproduce_state] The use of other attributes than device state attributes is deprecated and will be removed in a future release. Invalid attributes are ['transition', 'brightness_pct']. Read the logs for further details: https://www.home-assistant.io/integrations/scene/
2020-11-15 23:01:46 WARNING (MainThread) [homeassistant.components.light.reproduce_state] The use of other attributes than device state attributes is deprecated and will be removed in a future release. Invalid attributes are ['transition', 'brightness_pct']. Read the logs for further details: https://www.home-assistant.io/integrations/scene/
2020-11-15 23:03:03 WARNING (MainThread) [homeassistant.components.light.reproduce_state] Unable to find entity light.living_room_chand
2020-11-15 23:03:03 WARNING (MainThread) [homeassistant.components.light.reproduce_state] The use of other attributes than device state attributes is deprecated and will be removed in a future release. Invalid attributes are ['transition']. Read the logs for further details: https://www.home-assistant.io/integrations/scene/
2020-11-15 23:03:03 WARNING (MainThread) [homeassistant.components.light.reproduce_state] The use of other attributes than device state attributes is deprecated and will be removed in a future release. Invalid attributes are ['transition', 'brightness_pct']. Read the logs for further details: https://www.home-assistant.io/integrations/scene/
2020-11-15 23:03:03 WARNING (MainThread) [homeassistant.components.light.reproduce_state] The use of other attributes than device state attributes is deprecated and will be removed in a future release. Invalid attributes are ['transition', 'brightness_pct']. Read the logs for further details: https://www.home-assistant.io/integrations/scene/
2020-11-15 23:03:03 WARNING (MainThread) [homeassistant.components.light.reproduce_state] The use of other attributes than device state attributes is deprecated and will be removed in a future release. Invalid attributes are ['transition', 'brightness_pct']. Read the logs for further details: https://www.home-assistant.io/integrations/scene/
2020-11-16 04:12:00 ERROR (Recorder) [homeassistant.components.recorder.util] Error executing query: (sqlite3.DatabaseError) database disk image is malformed
[SQL: SELECT states.state_id AS states_state_id, states.domain AS states_domain, states.entity_id AS states_entity_id, states.state AS states_state, states.attributes AS states_attributes, states.event_id AS states_event_id, states.last_changed AS states_last_changed, states.last_updated AS states_last_updated, states.created AS states_created, states.old_state_id AS states_old_state_id 
FROM states ORDER BY states.last_updated ASC
 LIMIT ? OFFSET ?]
[parameters: (1, 0)]
(Background on this error at: http://sqlalche.me/e/13/4xp6)
2020-11-16 04:12:00 ERROR (Recorder) [homeassistant.components.recorder.util] Error executing query: (sqlite3.DatabaseError) database disk image is malformed
[SQL: SELECT states.state_id AS states_state_id, states.domain AS states_domain, states.entity_id AS states_entity_id, states.state AS states_state, states.attributes AS states_attributes, states.event_id AS states_event_id, states.last_changed AS states_last_changed, states.last_updated AS states_last_updated, states.created AS states_created, states.old_state_id AS states_old_state_id 
FROM states ORDER BY states.last_updated ASC
 LIMIT ? OFFSET ?]
[parameters: (1, 0)]
(Background on this error at: http://sqlalche.me/e/13/4xp6)
2020-11-16 04:12:00 ERROR (Recorder) [homeassistant.components.recorder.util] Error executing query: (sqlite3.DatabaseError) database disk image is malformed
[SQL: SELECT states.state_id AS states_state_id, states.domain AS states_domain, states.entity_id AS states_entity_id, states.state AS states_state, states.attributes AS states_attributes, states.event_id AS states_event_id, states.last_changed AS states_last_changed, states.last_updated AS states_last_updated, states.created AS states_created, states.old_state_id AS states_old_state_id 
FROM states ORDER BY states.last_updated ASC
 LIMIT ? OFFSET ?]
[parameters: (1, 0)]
(Background on this error at: http://sqlalche.me/e/13/4xp6)
2020-11-16 04:12:00 ERROR (Recorder) [homeassistant.components.recorder.util] Error executing query: (sqlite3.DatabaseError) database disk image is malformed
[SQL: SELECT states.state_id AS states_state_id, states.domain AS states_domain, states.entity_id AS states_entity_id, states.state AS states_state, states.attributes AS states_attributes, states.event_id AS states_event_id, states.last_changed AS states_last_changed, states.last_updated AS states_last_updated, states.created AS states_created, states.old_state_id AS states_old_state_id 
FROM states ORDER BY states.last_updated ASC
 LIMIT ? OFFSET ?]
[parameters: (1, 0)]
(Background on this error at: http://sqlalche.me/e/13/4xp6)
2020-11-16 04:12:00 WARNING (Recorder) [homeassistant.components.recorder.purge] Error purging history: (sqlite3.DatabaseError) database disk image is malformed
[SQL: SELECT states.state_id AS states_state_id, states.domain AS states_domain, states.entity_id AS states_entity_id, states.state AS states_state, states.attributes AS states_attributes, states.event_id AS states_event_id, states.last_changed AS states_last_changed, states.last_updated AS states_last_updated, states.created AS states_created, states.old_state_id AS states_old_state_id 
FROM states ORDER BY states.last_updated ASC
 LIMIT ? OFFSET ?]
[parameters: (1, 0)]
(Background on this error at: http://sqlalche.me/e/13/4xp6)
2020-11-16 06:00:39 WARNING (MainThread) [homeassistant.components.mobile_app.notify] Found duplicate device name iPhone
2020-11-16 06:00:39 WARNING (MainThread) [homeassistant.components.mobile_app.notify] Found duplicate device name iPhone
2020-11-16 07:16:59 WARNING (MainThread) [homeassistant.components.light.reproduce_state] The use of other attributes than device state attributes is deprecated and will be removed in a future release. Invalid attributes are ['brightness_pct', 'transition']. Read the logs for further details: https://www.home-assistant.io/integrations/scene/
2020-11-16 07:16:59 WARNING (MainThread) [homeassistant.components.light.reproduce_state] The use of other attributes than device state attributes is deprecated and will be removed in a future release. Invalid attributes are ['brightness_pct']. Read the logs for further details: https://www.home-assistant.io/integrations/scene/
2020-11-16 07:16:59 WARNING (MainThread) [homeassistant.components.light.reproduce_state] The use of other attributes than device state attributes is deprecated and will be removed in a future release. Invalid attributes are ['brightness_pct']. Read the logs for further details: https://www.home-assistant.io/integrations/scene/
2020-11-16 07:16:59 WARNING (MainThread) [homeassistant.components.light.reproduce_state] The use of other attributes than device state attributes is deprecated and will be removed in a future release. Invalid attributes are ['brightness_pct']. Read the logs for further details: https://www.home-assistant.io/integrations/scene/
2020-11-16 07:16:59 WARNING (MainThread) [homeassistant.components.light.reproduce_state] The use of other attributes than device state attributes is deprecated and will be removed in a future release. Invalid attributes are ['brightness_pct']. Read the logs for further details: https://www.home-assistant.io/integrations/scene/
2020-11-16 07:16:59 WARNING (MainThread) [homeassistant.components.light.reproduce_state] The use of other attributes than device state attributes is deprecated and will be removed in a future release. Invalid attributes are ['brightness_pct']. Read the logs for further details: https://www.home-assistant.io/integrations/scene/
2020-11-16 16:37:02 ERROR (MainThread) [homeassistant.components.automation.turn_outdoor_lights_on] turn outdoor lights on: Error executing script. Invalid data for call_service at pos 3: must contain at least one of entity_id, area_id.
2020-11-16 16:37:02 ERROR (MainThread) [homeassistant.components.automation.turn_outdoor_lights_on] While executing automation automation.turn_outdoor_lights_on
Traceback (most recent call last):
  File "/usr/local/lib/python3.8/site-packages/voluptuous/schema_builder.py", line 272, in __call__
    return self._compiled([], data)
  File "/usr/local/lib/python3.8/site-packages/voluptuous/schema_builder.py", line 817, in validate_callable
    return schema(data)
  File "/usr/src/homeassistant/homeassistant/helpers/config_validation.py", line 129, in validate
    raise vol.Invalid("must contain at least one of {}.".format(", ".join(keys)))
voluptuous.error.Invalid: must contain at least one of entity_id, area_id.

During handling of the above exception, another exception occurred:

Traceback (most recent call last):
  File "/usr/src/homeassistant/homeassistant/components/automation/__init__.py", line 426, in async_trigger
    await self.action_script.async_run(
  File "/usr/src/homeassistant/homeassistant/helpers/script.py", line 1010, in async_run
    await asyncio.shield(run.async_run())
  File "/usr/src/homeassistant/homeassistant/helpers/script.py", line 245, in async_run
    await self._async_step(log_exceptions=False)
  File "/usr/src/homeassistant/homeassistant/helpers/script.py", line 253, in _async_step
    await getattr(
  File "/usr/src/homeassistant/homeassistant/helpers/script.py", line 460, in _async_call_service_step
    await service_task
  File "/usr/src/homeassistant/homeassistant/core.py", line 1402, in async_call
    processed_data = handler.schema(service_data)
  File "/usr/local/lib/python3.8/site-packages/voluptuous/validators.py", line 218, in __call__
    return self._exec((Schema(val) for val in self.validators), v)
  File "/usr/local/lib/python3.8/site-packages/voluptuous/validators.py", line 340, in _exec
    raise e if self.msg is None else AllInvalid(self.msg, path=path)
  File "/usr/local/lib/python3.8/site-packages/voluptuous/validators.py", line 336, in _exec
    v = func(v)
  File "/usr/local/lib/python3.8/site-packages/voluptuous/schema_builder.py", line 276, in __call__
    raise er.MultipleInvalid([e])
voluptuous.error.MultipleInvalid: must contain at least one of entity_id, area_id.
2020-11-16 17:11:29 WARNING (MainThread) [homeassistant.components.mobile_app.notify] Found duplicate device name iPhone
2020-11-16 17:11:29 WARNING (MainThread) [homeassistant.components.mobile_app.notify] Found duplicate device name iPhone
2020-11-16 17:11:29 WARNING (MainThread) [homeassistant.components.mobile_app.notify] Found duplicate device name iPhone
2020-11-16 17:11:29 WARNING (MainThread) [homeassistant.components.mobile_app.notify] Found duplicate device name iPhone
2020-11-16 17:43:36 WARNING (MainThread) [homeassistant.components.mobile_app.notify] Found duplicate device name iPhone
2020-11-16 17:43:36 WARNING (MainThread) [homeassistant.components.mobile_app.notify] Found duplicate device name iPhone
2020-11-16 21:22:52 WARNING (MainThread) [homeassistant.components.mobile_app.notify] Found duplicate device name iPhone
2020-11-16 21:22:52 WARNING (MainThread) [homeassistant.components.mobile_app.notify] Found duplicate device name iPhone
2020-11-16 23:18:18 WARNING (MainThread) [homeassistant.components.light.reproduce_state] Unable to find entity light.living_room_chand
2020-11-16 23:18:18 WARNING (MainThread) [homeassistant.components.light.reproduce_state] The use of other attributes than device state attributes is deprecated and will be removed in a future release. Invalid attributes are ['transition']. Read the logs for further details: https://www.home-assistant.io/integrations/scene/
2020-11-16 23:18:18 WARNING (MainThread) [homeassistant.components.light.reproduce_state] The use of other attributes than device state attributes is deprecated and will be removed in a future release. Invalid attributes are ['transition', 'brightness_pct']. Read the logs for further details: https://www.home-assistant.io/integrations/scene/
2020-11-16 23:18:18 WARNING (MainThread) [homeassistant.components.light.reproduce_state] The use of other attributes than device state attributes is deprecated and will be removed in a future release. Invalid attributes are ['transition', 'brightness_pct']. Read the logs for further details: https://www.home-assistant.io/integrations/scene/
2020-11-16 23:18:18 WARNING (MainThread) [homeassistant.components.light.reproduce_state] The use of other attributes than device state attributes is deprecated and will be removed in a future release. Invalid attributes are ['transition', 'brightness_pct']. Read the logs for further details: https://www.home-assistant.io/integrations/scene/
2020-11-17 00:22:24 ERROR (MainThread) [pyhaversion] Timeout error fetching version information from PyPi, 
2020-11-17 00:22:24 WARNING (MainThread) [custom_components.breaking_changes] Could not get version data.
2020-11-17 04:12:00 ERROR (Recorder) [homeassistant.components.recorder.util] Error executing query: (sqlite3.DatabaseError) database disk image is malformed
[SQL: SELECT states.state_id AS states_state_id, states.domain AS states_domain, states.entity_id AS states_entity_id, states.state AS states_state, states.attributes AS states_attributes, states.event_id AS states_event_id, states.last_changed AS states_last_changed, states.last_updated AS states_last_updated, states.created AS states_created, states.old_state_id AS states_old_state_id 
FROM states ORDER BY states.last_updated ASC
 LIMIT ? OFFSET ?]
[parameters: (1, 0)]
(Background on this error at: http://sqlalche.me/e/13/4xp6)
2020-11-17 04:12:00 ERROR (Recorder) [homeassistant.components.recorder.util] Error executing query: (sqlite3.DatabaseError) database disk image is malformed
[SQL: SELECT states.state_id AS states_state_id, states.domain AS states_domain, states.entity_id AS states_entity_id, states.state AS states_state, states.attributes AS states_attributes, states.event_id AS states_event_id, states.last_changed AS states_last_changed, states.last_updated AS states_last_updated, states.created AS states_created, states.old_state_id AS states_old_state_id 
FROM states ORDER BY states.last_updated ASC
 LIMIT ? OFFSET ?]
[parameters: (1, 0)]
(Background on this error at: http://sqlalche.me/e/13/4xp6)
2020-11-17 04:12:00 ERROR (Recorder) [homeassistant.components.recorder.util] Error executing query: (sqlite3.DatabaseError) database disk image is malformed
[SQL: SELECT states.state_id AS states_state_id, states.domain AS states_domain, states.entity_id AS states_entity_id, states.state AS states_state, states.attributes AS states_attributes, states.event_id AS states_event_id, states.last_changed AS states_last_changed, states.last_updated AS states_last_updated, states.created AS states_created, states.old_state_id AS states_old_state_id 
FROM states ORDER BY states.last_updated ASC
 LIMIT ? OFFSET ?]
[parameters: (1, 0)]
(Background on this error at: http://sqlalche.me/e/13/4xp6)
2020-11-17 04:12:00 ERROR (Recorder) [homeassistant.components.recorder.util] Error executing query: (sqlite3.DatabaseError) database disk image is malformed
[SQL: SELECT states.state_id AS states_state_id, states.domain AS states_domain, states.entity_id AS states_entity_id, states.state AS states_state, states.attributes AS states_attributes, states.event_id AS states_event_id, states.last_changed AS states_last_changed, states.last_updated AS states_last_updated, states.created AS states_created, states.old_state_id AS states_old_state_id 
FROM states ORDER BY states.last_updated ASC
 LIMIT ? OFFSET ?]
[parameters: (1, 0)]
(Background on this error at: http://sqlalche.me/e/13/4xp6)
2020-11-17 04:12:00 WARNING (Recorder) [homeassistant.components.recorder.purge] Error purging history: (sqlite3.DatabaseError) database disk image is malformed
[SQL: SELECT states.state_id AS states_state_id, states.domain AS states_domain, states.entity_id AS states_entity_id, states.state AS states_state, states.attributes AS states_attributes, states.event_id AS states_event_id, states.last_changed AS states_last_changed, states.last_updated AS states_last_updated, states.created AS states_created, states.old_state_id AS states_old_state_id 
FROM states ORDER BY states.last_updated ASC
 LIMIT ? OFFSET ?]
[parameters: (1, 0)]
(Background on this error at: http://sqlalche.me/e/13/4xp6)
2020-11-17 07:16:08 WARNING (MainThread) [homeassistant.components.light.reproduce_state] The use of other attributes than device state attributes is deprecated and will be removed in a future release. Invalid attributes are ['brightness_pct', 'transition']. Read the logs for further details: https://www.home-assistant.io/integrations/scene/
2020-11-17 07:16:08 WARNING (MainThread) [homeassistant.components.light.reproduce_state] The use of other attributes than device state attributes is deprecated and will be removed in a future release. Invalid attributes are ['brightness_pct']. Read the logs for further details: https://www.home-assistant.io/integrations/scene/
2020-11-17 07:16:08 WARNING (MainThread) [homeassistant.components.light.reproduce_state] The use of other attributes than device state attributes is deprecated and will be removed in a future release. Invalid attributes are ['brightness_pct']. Read the logs for further details: https://www.home-assistant.io/integrations/scene/
2020-11-17 07:16:08 WARNING (MainThread) [homeassistant.components.light.reproduce_state] The use of other attributes than device state attributes is deprecated and will be removed in a future release. Invalid attributes are ['brightness_pct']. Read the logs for further details: https://www.home-assistant.io/integrations/scene/
2020-11-17 07:16:08 WARNING (MainThread) [homeassistant.components.light.reproduce_state] The use of other attributes than device state attributes is deprecated and will be removed in a future release. Invalid attributes are ['brightness_pct']. Read the logs for further details: https://www.home-assistant.io/integrations/scene/
2020-11-17 07:16:08 WARNING (MainThread) [homeassistant.components.light.reproduce_state] The use of other attributes than device state attributes is deprecated and will be removed in a future release. Invalid attributes are ['brightness_pct']. Read the logs for further details: https://www.home-assistant.io/integrations/scene/
2020-11-17 07:57:16 WARNING (MainThread) [homeassistant.components.mobile_app.notify] Found duplicate device name iPhone
2020-11-17 07:57:16 WARNING (MainThread) [homeassistant.components.mobile_app.notify] Found duplicate device name iPhone
